Workbook

Sheet 안내
B2: 다문화학생 한국어 학습 콘텐츠 커리큘럼(안)
B3: 한국어능력 초기진단 체크리스트(초1~2·초3~4·초5~6, 듣기·말하기·읽기·쓰기)의 성취수준을 1차시 1성취수준으로 옮긴 제작용 커리큘럼입니다.
B5: 시트 | C5: 내용
B6: 현황 요약 | C6: 학년군·영역별 차시 수, 진단 문항 수, 제작 상태 집계(자동 계산)
B7: 커리큘럼 | C7: 204차시 전체. 차시명·학습 목표·활동 구성·활동 유형·주제 연계·기술 고려·우선순위·제작 상태
B8: 진단 문항 | C8: 원고의 진단 문항 514개(코드, 체크리스트 문항, 교사 발문·절차, 학생 수행)
B9: 원고 확인 사항 | C9: 원고에서 발견한 번호·표기·맞춤법 불일치 목록
B10: 제작 체크리스트 | C10: 듣기06 제작 경험을 바탕으로 정리한 공통 준비·고려 사항
B12: 구성 원칙
B13: • 1차시 = 성취수준 1개. 학년군마다 듣기 16·말하기 20·읽기 16·쓰기 16 = 68차시, 전체 204차시.
B14: • 차시 번호는 영역 안에서 수준→성취수준 순서로 매김(1수준 01~04, 2수준 05~08 …, 말하기는 수준마다 5개). 차시 ID 예: 초1~2-듣기-06.
B15: • 활동 4개: ① 낱말·표현 익히기 → ② 기본 과제 → ③ 확장 과제 → ④ 진단 문항과 같은 형태로 확인. ④를 마치면 해당 진단 문항으로 재진단 가능.
B16: • 같은 학년군에서 주제가 같은 차시(예: 준비물)는 이미지·어휘를 함께 씀. "같은 주제 차시" 열 참고.
B17: • 차시명·학습 목표·활동 구성·활동 유형·우선순위는 제안(초안)입니다. 성취수준·진단 문항은 원고 그대로입니다.
B19: 입력 방법
B20: • 노란 칸(커리큘럼 시트의 제작 상태·담당·비고)만 입력하세요. 제작 상태는 목록에서 고릅니다: 예정 / 제작중 / 검수중 / 완료 / 확인 필요.
B21: • 현황 요약 시트는 입력한 상태를 자동으로 집계합니다.
B22: • 예시: 초3~4-듣기-06 → 제작 상태 "완료", 비고에 듣기06 메모가 들어 있습니다.
B24: 수준 정의(통합 성취수준, 원고 그대로)
B25: 학년군 | C25: 1수준 | D25: 2수준 | E25: 3수준 | F25: 4수준
B26: 초1~2 | C26: 한국어의 자모를 익히고, 단어와 짧은 문장 수준에서 기초적인 의사소통(인사)을 할 수 있다. | D26: 생활 속에 필요한 기본적인 내용을 짧은 문장으로 의사소통을 할 수 있다. | E26: 일상에서 자신의 관심사에 대해 짧은 글과 말로 의사소통을 할 수 있고, 수업에 어느 정도 참여할 수 있다. | F26: 일상에서 필요한 내용을 글과 말로 의사소통을 할 수 있고, 수업과 학교생활에 참여할 수 있다.
B27: 초3~4 | C27: 한글을 익히고, 간단한 단어와 짧은 문장을 중심으로 기초적인 의사소통을 할 수 있다. | D27: 일상과 학교생활에서 자주 사용하는 기본적인 내용을 문장으로 의사소통할 수 있다. | E27: 친숙한 주제에 대한 주요 내용을 이해하고 문장으로 표현할 수 있으며, 수업에 부분적으로 참여할 수 있다. | F27: 일상과 수업에서 필요한 내용을 이해하고 의사소통을 할 수 있으며 수업과 학교생활에 참여할 수 있다.
B28: 초5~6 | C28: 한글을 익히고, 간단한 단어와 짧은 문장을 중심으로 기본적인 의사소통을 할 수 있다. | D28: 일상과 학교생활에서 자주 사용하는 기본적인 내용을 파악하고 표현하며, 의사소통을 할 수 있다. | E28: 친숙한 주제에 관한 주요 내용을 파악하고 표현할 수 있으며, 수업에 참여할 수 있다. | F28: 일상과 수업에서 필요한 내용을 파악하고 표현할 수 있으며, 수업과 학교생활에 참여할 수 있다.
B30: 출처
B31: • 초1_2·초3_4·초5_6 초기진단 체크리스트 진단도구(듣기·말하기·읽기·쓰기) PDF 12종
B32: • ① (초등)수준별, 영역별 성취 수준.pdf / 초기진단 체크리스트 활용 안내문(교사용·일반용).pdf
B33: • 듣기06 제작 자료(claude_prompt.md, 참고 HTML). 진단 문항 텍스트는 PDF에서 자동 추출했으므로 일부 줄바꿈·누락이 있을 수 있음

Sheet 현황 요약
A1: 현황 요약
A2: 커리큘럼 시트의 제작 상태를 바꾸면 자동으로 다시 계산됩니다.
A4: 학년군 | B4: 영역 | C4: 차시 수 | D4: 진단 문항 수 | E4: 예정 | F4: 제작중 | G4: 검수중 | H4: 완료 | I4: 확인 필요 | J4: 완료율
A5: 초1~2 | B5: 듣기 | C5: =SUMPRODUCT((커리큘럼!$B$2:$B$205=$A5)*(커리큘럼!$C$2:$C$205=$B5)) -> 16 | D5: =SUMPRODUCT(('진단 문항'!$A$2:$A$515=$A5)*('진단 문항'!$B$2:$B$515=$B5)) -> 39 | E5: =SUMPRODUCT((커리큘럼!$B$2:$B$205=$A5)*(커리큘럼!$C$2:$C$205=$B5)*(커리큘럼!$R$2:$R$205="예정")) -> 16 | F5: =SUMPRODUCT((커리큘럼!$B$2:$B$205=$A5)*(커리큘럼!$C$2:$C$205=$B5)*(커리큘럼!$R$2:$R$205="제작중")) -> 0 | G5: =SUMPRODUCT((커리큘럼!$B$2:$B$205=$A5)*(커리큘럼!$C$2:$C$205=$B5)*(커리큘럼!$R$2:$R$205="검수중")) -> 0 | H5: =SUMPRODUCT((커리큘럼!$B$2:$B$205=$A5)*(커리큘럼!$C$2:$C$205=$B5)*(커리큘럼!$R$2:$R$205="완료")) -> 0 | I5: =SUMPRODUCT((커리큘럼!$B$2:$B$205=$A5)*(커리큘럼!$C$2:$C$205=$B5)*(커리큘럼!$R$2:$R$205="확인 필요")) -> 0 | J5: =IF(C5=0,0,H5/C5) -> 0
A6: 초1~2 | B6: 말하기 | C6: =SUMPRODUCT((커리큘럼!$B$2:$B$205=$A6)*(커리큘럼!$C$2:$C$205=$B6)) -> 20 | D6: =SUMPRODUCT(('진단 문항'!$A$2:$A$515=$A6)*('진단 문항'!$B$2:$B$515=$B6)) -> 55 | E6: =SUMPRODUCT((커리큘럼!$B$2:$B$205=$A6)*(커리큘럼!$C$2:$C$205=$B6)*(커리큘럼!$R$2:$R$205="예정")) -> 20 | F6: =SUMPRODUCT((커리큘럼!$B$2:$B$205=$A6)*(커리큘럼!$C$2:$C$205=$B6)*(커리큘럼!$R$2:$R$205="제작중")) -> 0 | G6: =SUMPRODUCT((커리큘럼!$B$2:$B$205=$A6)*(커리큘럼!$C$2:$C$205=$B6)*(커리큘럼!$R$2:$R$205="검수중")) -> 0 | H6: =SUMPRODUCT((커리큘럼!$B$2:$B$205=$A6)*(커리큘럼!$C$2:$C$205=$B6)*(커리큘럼!$R$2:$R$205="완료")) -> 0 | I6: =SUMPRODUCT((커리큘럼!$B$2:$B$205=$A6)*(커리큘럼!$C$2:$C$205=$B6)*(커리큘럼!$R$2:$R$205="확인 필요")) -> 0 | J6: =IF(C6=0,0,H6/C6) -> 0
A7: 초1~2 | B7: 읽기 | C7: =SUMPRODUCT((커리큘럼!$B$2:$B$205=$A7)*(커리큘럼!$C$2:$C$205=$B7)) -> 16 | D7: =SUMPRODUCT(('진단 문항'!$A$2:$A$515=$A7)*('진단 문항'!$B$2:$B$515=$B7)) -> 47 | E7: =SUMPRODUCT((커리큘럼!$B$2:$B$205=$A7)*(커리큘럼!$C$2:$C$205=$B7)*(커리큘럼!$R$2:$R$205="예정")) -> 16 | F7: =SUMPRODUCT((커리큘럼!$B$2:$B$205=$A7)*(커리큘럼!$C$2:$C$205=$B7)*(커리큘럼!$R$2:$R$205="제작중")) -> 0 | G7: =SUMPRODUCT((커리큘럼!$B$2:$B$205=$A7)*(커리큘럼!$C$2:$C$205=$B7)*(커리큘럼!$R$2:$R$205="검수중")) -> 0 | H7: =SUMPRODUCT((커리큘럼!$B$2:$B$205=$A7)*(커리큘럼!$C$2:$C$205=$B7)*(커리큘럼!$R$2:$R$205="완료")) -> 0 | I7: =SUMPRODUCT((커리큘럼!$B$2:$B$205=$A7)*(커리큘럼!$C$2:$C$205=$B7)*(커리큘럼!$R$2:$R$205="확인 필요")) -> 0 | J7: =IF(C7=0,0,H7/C7) -> 0
A8: 초1~2 | B8: 쓰기 | C8: =SUMPRODUCT((커리큘럼!$B$2:$B$205=$A8)*(커리큘럼!$C$2:$C$205=$B8)) -> 16 | D8: =SUMPRODUCT(('진단 문항'!$A$2:$A$515=$A8)*('진단 문항'!$B$2:$B$515=$B8)) -> 36 | E8: =SUMPRODUCT((커리큘럼!$B$2:$B$205=$A8)*(커리큘럼!$C$2:$C$205=$B8)*(커리큘럼!$R$2:$R$205="예정")) -> 16 | F8: =SUMPRODUCT((커리큘럼!$B$2:$B$205=$A8)*(커리큘럼!$C$2:$C$205=$B8)*(커리큘럼!$R$2:$R$205="제작중")) -> 0 | G8: =SUMPRODUCT((커리큘럼!$B$2:$B$205=$A8)*(커리큘럼!$C$2:$C$205=$B8)*(커리큘럼!$R$2:$R$205="검수중")) -> 0 | H8: =SUMPRODUCT((커리큘럼!$B$2:$B$205=$A8)*(커리큘럼!$C$2:$C$205=$B8)*(커리큘럼!$R$2:$R$205="완료")) -> 0 | I8: =SUMPRODUCT((커리큘럼!$B$2:$B$205=$A8)*(커리큘럼!$C$2:$C$205=$B8)*(커리큘럼!$R$2:$R$205="확인 필요")) -> 0 | J8: =IF(C8=0,0,H8/C8) -> 0
A9: 초1~2 | B9: 소계 | C9: =SUM(C5:C8) -> 68 | D9: =SUM(D5:D8) -> 177 | E9: =SUM(E5:E8) -> 68 | F9: =SUM(F5:F8) -> 0 | G9: =SUM(G5:G8) -> 0 | H9: =SUM(H5:H8) -> 0 | I9: =SUM(I5:I8) -> 0 | J9: =IF(C9=0,0,H9/C9) -> 0
A10: 초3~4 | B10: 듣기 | C10: =SUMPRODUCT((커리큘럼!$B$2:$B$205=$A10)*(커리큘럼!$C$2:$C$205=$B10)) -> 16 | D10: =SUMPRODUCT(('진단 문항'!$A$2:$A$515=$A10)*('진단 문항'!$B$2:$B$515=$B10)) -> 34 | E10: =SUMPRODUCT((커리큘럼!$B$2:$B$205=$A10)*(커리큘럼!$C$2:$C$205=$B10)*(커리큘럼!$R$2:$R$205="예정")) -> 15 | F10: =SUMPRODUCT((커리큘럼!$B$2:$B$205=$A10)*(커리큘럼!$C$2:$C$205=$B10)*(커리큘럼!$R$2:$R$205="제작중")) -> 0 | G10: =SUMPRODUCT((커리큘럼!$B$2:$B$205=$A10)*(커리큘럼!$C$2:$C$205=$B10)*(커리큘럼!$R$2:$R$205="검수중")) -> 0 | H10: =SUMPRODUCT((커리큘럼!$B$2:$B$205=$A10)*(커리큘럼!$C$2:$C$205=$B10)*(커리큘럼!$R$2:$R$205="완료")) -> 1 | I10: =SUMPRODUCT((커리큘럼!$B$2:$B$205=$A10)*(커리큘럼!$C$2:$C$205=$B10)*(커리큘럼!$R$2:$R$205="확인 필요")) -> 0 | J10: =IF(C10=0,0,H10/C10) -> 0.0625
A11: 초3~4 | B11: 말하기 | C11: =SUMPRODUCT((커리큘럼!$B$2:$B$205=$A11)*(커리큘럼!$C$2:$C$205=$B11)) -> 20 | D11: =SUMPRODUCT(('진단 문항'!$A$2:$A$515=$A11)*('진단 문항'!$B$2:$B$515=$B11)) -> 50 | E11: =SUMPRODUCT((커리큘럼!$B$2:$B$205=$A11)*(커리큘럼!$C$2:$C$205=$B11)*(커리큘럼!$R$2:$R$205="예정")) -> 20 | F11: =SUMPRODUCT((커리큘럼!$B$2:$B$205=$A11)*(커리큘럼!$C$2:$C$205=$B11)*(커리큘럼!$R$2:$R$205="제작중")) -> 0 | G11: =SUMPRODUCT((커리큘럼!$B$2:$B$205=$A11)*(커리큘럼!$C$2:$C$205=$B11)*(커리큘럼!$R$2:$R$205="검수중")) -> 0 | H11: =SUMPRODUCT((커리큘럼!$B$2:$B$205=$A11)*(커리큘럼!$C$2:$C$205=$B11)*(커리큘럼!$R$2:$R$205="완료")) -> 0 | I11: =SUMPRODUCT((커리큘럼!$B$2:$B$205=$A11)*(커리큘럼!$C$2:$C$205=$B11)*(커리큘럼!$R$2:$R$205="확인 필요")) -> 0 | J11: =IF(C11=0,0,H11/C11) -> 0
A12: 초3~4 | B12: 읽기 | C12: =SUMPRODUCT((커리큘럼!$B$2:$B$205=$A12)*(커리큘럼!$C$2:$C$205=$B12)) -> 16 | D12: =SUMPRODUCT(('진단 문항'!$A$2:$A$515=$A12)*('진단 문항'!$B$2:$B$515=$B12)) -> 38 | E12: =SUMPRODUCT((커리큘럼!$B$2:$B$205=$A12)*(커리큘럼!$C$2:$C$205=$B12)*(커리큘럼!$R$2:$R$205="예정")) -> 16 | F12: =SUMPRODUCT((커리큘럼!$B$2:$B$205=$A12)*(커리큘럼!$C$2:$C$205=$B12)*(커리큘럼!$R$2:$R$205="제작중")) -> 0 | G12: =SUMPRODUCT((커리큘럼!$B$2:$B$205=$A12)*(커리큘럼!$C$2:$C$205=$B12)*(커리큘럼!$R$2:$R$205="검수중")) -> 0 | H12: =SUMPRODUCT((커리큘럼!$B$2:$B$205=$A12)*(커리큘럼!$C$2:$C$205=$B12)*(커리큘럼!$R$2:$R$205="완료")) -> 0 | I12: =SUMPRODUCT((커리큘럼!$B$2:$B$205=$A12)*(커리큘럼!$C$2:$C$205=$B12)*(커리큘럼!$R$2:$R$205="확인 필요")) -> 0 | J12: =IF(C12=0,0,H12/C12) -> 0
A13: 초3~4 | B13: 쓰기 | C13: =SUMPRODUCT((커리큘럼!$B$2:$B$205=$A13)*(커리큘럼!$C$2:$C$205=$B13)) -> 16 | D13: =SUMPRODUCT(('진단 문항'!$A$2:$A$515=$A13)*('진단 문항'!$B$2:$B$515=$B13)) -> 35 | E13: =SUMPRODUCT((커리큘럼!$B$2:$B$205=$A13)*(커리큘럼!$C$2:$C$205=$B13)*(커리큘럼!$R$2:$R$205="예정")) -> 16 | F13: =SUMPRODUCT((커리큘럼!$B$2:$B$205=$A13)*(커리큘럼!$C$2:$C$205=$B13)*(커리큘럼!$R$2:$R$205="제작중")) -> 0 | G13: =SUMPRODUCT((커리큘럼!$B$2:$B$205=$A13)*(커리큘럼!$C$2:$C$205=$B13)*(커리큘럼!$R$2:$R$205="검수중")) -> 0 | H13: =SUMPRODUCT((커리큘럼!$B$2:$B$205=$A13)*(커리큘럼!$C$2:$C$205=$B13)*(커리큘럼!$R$2:$R$205="완료")) -> 0 | I13: =SUMPRODUCT((커리큘럼!$B$2:$B$205=$A13)*(커리큘럼!$C$2:$C$205=$B13)*(커리큘럼!$R$2:$R$205="확인 필요")) -> 0 | J13: =IF(C13=0,0,H13/C13) -> 0
A14: 초3~4 | B14: 소계 | C14: =SUM(C10:C13) -> 68 | D14: =SUM(D10:D13) -> 157 | E14: =SUM(E10:E13) -> 67 | F14: =SUM(F10:F13) -> 0 | G14: =SUM(G10:G13) -> 0 | H14: =SUM(H10:H13) -> 1 | I14: =SUM(I10:I13) -> 0 | J14: =IF(C14=0,0,H14/C14) -> 0.014705882
A15: 초5~6 | B15: 듣기 | C15: =SUMPRODUCT((커리큘럼!$B$2:$B$205=$A15)*(커리큘럼!$C$2:$C$205=$B15)) -> 16 | D15: =SUMPRODUCT(('진단 문항'!$A$2:$A$515=$A15)*('진단 문항'!$B$2:$B$515=$B15)) -> 43 | E15: =SUMPRODUCT((커리큘럼!$B$2:$B$205=$A15)*(커리큘럼!$C$2:$C$205=$B15)*(커리큘럼!$R$2:$R$205="예정")) -> 16 | F15: =SUMPRODUCT((커리큘럼!$B$2:$B$205=$A15)*(커리큘럼!$C$2:$C$205=$B15)*(커리큘럼!$R$2:$R$205="제작중")) -> 0 | G15: =SUMPRODUCT((커리큘럼!$B$2:$B$205=$A15)*(커리큘럼!$C$2:$C$205=$B15)*(커리큘럼!$R$2:$R$205="검수중")) -> 0 | H15: =SUMPRODUCT((커리큘럼!$B$2:$B$205=$A15)*(커리큘럼!$C$2:$C$205=$B15)*(커리큘럼!$R$2:$R$205="완료")) -> 0 | I15: =SUMPRODUCT((커리큘럼!$B$2:$B$205=$A15)*(커리큘럼!$C$2:$C$205=$B15)*(커리큘럼!$R$2:$R$205="확인 필요")) -> 0 | J15: =IF(C15=0,0,H15/C15) -> 0
A16: 초5~6 | B16: 말하기 | C16: =SUMPRODUCT((커리큘럼!$B$2:$B$205=$A16)*(커리큘럼!$C$2:$C$205=$B16)) -> 20 | D16: =SUMPRODUCT(('진단 문항'!$A$2:$A$515=$A16)*('진단 문항'!$B$2:$B$515=$B16)) -> 58 | E16: =SUMPRODUCT((커리큘럼!$B$2:$B$205=$A16)*(커리큘럼!$C$2:$C$205=$B16)*(커리큘럼!$R$2:$R$205="예정")) -> 20 | F16: =SUMPRODUCT((커리큘럼!$B$2:$B$205=$A16)*(커리큘럼!$C$2:$C$205=$B16)*(커리큘럼!$R$2:$R$205="제작중")) -> 0 | G16: =SUMPRODUCT((커리큘럼!$B$2:$B$205=$A16)*(커리큘럼!$C$2:$C$205=$B16)*(커리큘럼!$R$2:$R$205="검수중")) -> 0 | H16: =SUMPRODUCT((커리큘럼!$B$2:$B$205=$A16)*(커리큘럼!$C$2:$C$205=$B16)*(커리큘럼!$R$2:$R$205="완료")) -> 0 | I16: =SUMPRODUCT((커리큘럼!$B$2:$B$205=$A16)*(커리큘럼!$C$2:$C$205=$B16)*(커리큘럼!$R$2:$R$205="확인 필요")) -> 0 | J16: =IF(C16=0,0,H16/C16) -> 0
A17: 초5~6 | B17: 읽기 | C17: =SUMPRODUCT((커리큘럼!$B$2:$B$205=$A17)*(커리큘럼!$C$2:$C$205=$B17)) -> 16 | D17: =SUMPRODUCT(('진단 문항'!$A$2:$A$515=$A17)*('진단 문항'!$B$2:$B$515=$B17)) -> 41 | E17: =SUMPRODUCT((커리큘럼!$B$2:$B$205=$A17)*(커리큘럼!$C$2:$C$205=$B17)*(커리큘럼!$R$2:$R$205="예정")) -> 16 | F17: =SUMPRODUCT((커리큘럼!$B$2:$B$205=$A17)*(커리큘럼!$C$2:$C$205=$B17)*(커리큘럼!$R$2:$R$205="제작중")) -> 0 | G17: =SUMPRODUCT((커리큘럼!$B$2:$B$205=$A17)*(커리큘럼!$C$2:$C$205=$B17)*(커리큘럼!$R$2:$R$205="검수중")) -> 0 | H17: =SUMPRODUCT((커리큘럼!$B$2:$B$205=$A17)*(커리큘럼!$C$2:$C$205=$B17)*(커리큘럼!$R$2:$R$205="완료")) -> 0 | I17: =SUMPRODUCT((커리큘럼!$B$2:$B$205=$A17)*(커리큘럼!$C$2:$C$205=$B17)*(커리큘럼!$R$2:$R$205="확인 필요")) -> 0 | J17: =IF(C17=0,0,H17/C17) -> 0
A18: 초5~6 | B18: 쓰기 | C18: =SUMPRODUCT((커리큘럼!$B$2:$B$205=$A18)*(커리큘럼!$C$2:$C$205=$B18)) -> 16 | D18: =SUMPRODUCT(('진단 문항'!$A$2:$A$515=$A18)*('진단 문항'!$B$2:$B$515=$B18)) -> 38 | E18: =SUMPRODUCT((커리큘럼!$B$2:$B$205=$A18)*(커리큘럼!$C$2:$C$205=$B18)*(커리큘럼!$R$2:$R$205="예정")) -> 16 | F18: =SUMPRODUCT((커리큘럼!$B$2:$B$205=$A18)*(커리큘럼!$C$2:$C$205=$B18)*(커리큘럼!$R$2:$R$205="제작중")) -> 0 | G18: =SUMPRODUCT((커리큘럼!$B$2:$B$205=$A18)*(커리큘럼!$C$2:$C$205=$B18)*(커리큘럼!$R$2:$R$205="검수중")) -> 0 | H18: =SUMPRODUCT((커리큘럼!$B$2:$B$205=$A18)*(커리큘럼!$C$2:$C$205=$B18)*(커리큘럼!$R$2:$R$205="완료")) -> 0 | I18: =SUMPRODUCT((커리큘럼!$B$2:$B$205=$A18)*(커리큘럼!$C$2:$C$205=$B18)*(커리큘럼!$R$2:$R$205="확인 필요")) -> 0 | J18: =IF(C18=0,0,H18/C18) -> 0
A19: 초5~6 | B19: 소계 | C19: =SUM(C15:C18) -> 68 | D19: =SUM(D15:D18) -> 180 | E19: =SUM(E15:E18) -> 68 | F19: =SUM(F15:F18) -> 0 | G19: =SUM(G15:G18) -> 0 | H19: =SUM(H15:H18) -> 0 | I19: =SUM(I15:I18) -> 0 | J19: =IF(C19=0,0,H19/C19) -> 0
A20: 전체 | B20: 합계 | C20: =SUMIF($B$5:$B$19,"소계",C5:C19) -> 204 | D20: =SUMIF($B$5:$B$19,"소계",D5:D19) -> 514 | E20: =SUMIF($B$5:$B$19,"소계",E5:E19) -> 203 | F20: =SUMIF($B$5:$B$19,"소계",F5:F19) -> 0 | G20: =SUMIF($B$5:$B$19,"소계",G5:G19) -> 0 | H20: =SUMIF($B$5:$B$19,"소계",H5:H19) -> 1 | I20: =SUMIF($B$5:$B$19,"소계",I5:I19) -> 0 | J20: =IF(C20=0,0,H20/C20) -> 0.0049019608
A22: 우선순위별 차시 수(제안)
A23: 우선순위 | B23: 기준 | C23: 차시 수 | D23: 완료
A24: 1 | B24: 1~2수준 듣기·말하기 | C24: =COUNTIFS(커리큘럼!$Q$2:$Q$205,$A24) -> 54 | D24: =COUNTIFS(커리큘럼!$Q$2:$Q$205,$A24,커리큘럼!$R$2:$R$205,"완료") -> 1
A25: 2 | B25: 1~2수준 읽기·쓰기 | C25: =COUNTIFS(커리큘럼!$Q$2:$Q$205,$A25) -> 48 | D25: =COUNTIFS(커리큘럼!$Q$2:$Q$205,$A25,커리큘럼!$R$2:$R$205,"완료") -> 0
A26: 3 | B26: 3~4수준 전 영역 | C26: =COUNTIFS(커리큘럼!$Q$2:$Q$205,$A26) -> 102 | D26: =COUNTIFS(커리큘럼!$Q$2:$Q$205,$A26,커리큘럼!$R$2:$R$205,"완료") -> 0

Sheet 커리큘럼
A1: 차시 ID | B1: 학년군 | C1: 영역 | D1: 수준 | E1: 성취 수준 | F1: 차시 | G1: 차시명(안) | H1: 학습 목표(안) | I1: 성취수준(원문) | J1: 연계 진단 문항 | K1: 진단 문항 요지 | L1: 활동 구성(안) | M1: 주요 활동 유형 | N1: 주제 | O1: 같은 주제 차시 | P1: 기술 고려 | Q1: 우선 순위 | R1: 제작 상태 | S1: 담당 | T1: 비고
A2: 초1~2-듣기-01 | B2: 초1~2 | C2: 듣기 | D2: 1 | E2: 1 | F2: 1 | G2: 물건 이름을 듣고 찾아요 | H2: 짧고 쉬운 단어를 듣고 대상을 찾을 수 있어요. | I2: 짧고 쉬운 단어를 듣고 대상을 찾을 수 있다. | J2: L-1-1-1, L-1-1-2, L-1-1-3 | K2: L-1-1-1 교실 사물(연필, 지우개, 공책 등의 학용품 등)을 말하면, 해당 사물을 가리킨다. L-1-1-2 음식 이름(사과, 포도, 우유 등)을 말하면, 해당 사물을 가리킨다. L-1-1-3 생활 용품(모자, 가방, 책상, 의자 등)을 말하면, 해당 사물을 가리킨다. | L2: ① 낱말·표현 익히기: 연필, 지우개, 공책, 사과, 포도, 우유 ② 교실 사물(연필, 지우개, 공책 등의 학용품 등)을 말하면, 해당 사물을 가리킨다. ③ 음식 이름(사과, 포도, 우유 등)을 말하면, 해당 사물을 가리킨다. ④ 확인(진단형) 생활 용품(모자, 가방, 책상, 의자 등)을 말하면, 해당 사물을 가리킨다. | M2: 그림·보기 고르기 | N2: 교실 물건 | O2: 말하기-01, 읽기-02, 쓰기-04 | P2: 음성 필요(녹음 파일 권장) | Q2: 1 | R2: 예정
A3: 초1~2-듣기-02 | B3: 초1~2 | C3: 듣기 | D3: 1 | E3: 2 | F3: 2 | G3: 만나고 헤어질 때 인사해요 | H3: 간단한 인사말을 듣고 이해할 수 있어요. | I3: 간단한 인사말을 듣고 이해할 수 있다. | J3: L-1-2-1, L-1-2-2 | K3: L-1-2-1 만나고 헤어질 때 인사말(안녕하세요, 안녕히 계세요 등)에 답한다. L-1-2-2 만나고 헤어질 때 인사말(안녕히 가세요, 내일 봐요. 등)에 알맞은 표정이나 몸짓으로 반응한다. | L3: ① 낱말·표현 익히기: 안녕하세요, 안녕히 계세요, 안녕히 가세요, 내일 봐요 ② 만나고 헤어질 때 인사말(안녕하세요, 안녕히 계세요 등)에 답한다. ③ 만나고 헤어질 때 인사말(안녕히 가세요, 내일 봐요. 등)에 알맞은 표정이나 몸짓으로 반응한다. ④ 확인(진단형 L-1-2-1·L-1-2-2 섞기) | M3: 그림·보기 고르기 | N3: 인사 | O3: 말하기-02 | P3: 음성 필요(녹음 파일 권장) | Q3: 1 | R3: 예정
A4: 초1~2-듣기-03 | B4: 초1~2 | C4: 듣기 | D4: 1 | E4: 3 | F4: 3 | G4: 선생님 말을 듣고 움직여요 | H4: 교사의 간단한 지시를 듣고 따를 수 있어요. | I4: 교사의 간단한 지시를 듣고 따를 수 있다. | J4: L-1-3-1, L-1-3-2, L-1-3-3 | K4: L-1-3-1 교사의 행동 지시(일어나세요, 앉으세요.등)를 듣고, 해당 행동을 수행한다. L-1-3-2 교사의 방향을 포함한 지시(오른쪽으로 가세요. 교실로 들어가세요. 등)를 듣고, 해당 행동을 수행한다. L-1-3-3 목적어/부사어를 포함한 지시(책을 펴세요, 이름을 쓰세요. 자리에 앉으세요. 등)를 듣고, 해당 행동을 수행한다. | L4: ① 낱말·표현 익히기: 일어나세요, 앉으세요, 오른쪽으로 가세요, 교실로 들어가세요, 책을 펴세요, 이름을 쓰세요 ② 교사의 행동 지시(일어나세요, 앉으세요.등)를 듣고, 해당 행동을 수행한다. ③ 교사의 방향을 포함한 지시(오른쪽으로 가세요. 교실로 들어가세요. 등)를 듣고, 해당 행동을 수행한다. ④ 확인(진단형) 목적어/부사어를 포함한 지시(책을 펴세요, 이름을 쓰세요. 자리에 앉으세요. 등)를 듣고, 해당 행동을 수… | M4: 들은 대로 하기(그림 고르기) | N4: 교실 지시 | O4: 읽기-06 | P4: 음성 필요(녹음 파일 권장) | Q4: 1 | R4: 예정
A5: 초1~2-듣기-04 | B5: 초1~2 | C5: 듣기 | D5: 1 | E5: 4 | F5: 4 | G5: 소리를 듣고 자음과 모음을 찾아요 | H5: 자음과 모음을 듣고 식별할 수 있어요. | I5: 자음과 모음을 듣고 식별할 수 있다. | J5: L-1-4-1, L-1-4-2 | K5: L-1-4-1 모음(아, 야 등)을 말하면, 해당 모음을 고른다. L-1-4-2 자음의 음가(드,르 등)를 말하면, 해당 자음을 고른다. | L5: ① 낱말·표현 익히기: 아, 야, 드, 르 ② 모음(아, 야 등)을 말하면, 해당 모음을 고른다. ③ 자음의 음가(드,르 등)를 말하면, 해당 자음을 고른다. ④ 확인(진단형 L-1-4-1·L-1-4-2 섞기) | M5: 그림·보기 고르기 | N5: 한글 자모 | O5: 읽기-01, 읽기-04, 쓰기-01, 쓰기-02 | P5: 음성 필요(녹음 파일 권장) | Q5: 1 | R5: 예정
A6: 초1~2-듣기-05 | B6: 초1~2 | C6: 듣기 | D6: 2 | E6: 1 | F6: 5 | G6: 친구의 부탁을 듣고 도와줘요 | H6: 교실에서 자주 사용하는 기초적인 대화 내용을 이해할 수 있어요. | I6: 교실에서 자주 사용하는 기초적인 대화 내용을 이해할 수 있다. | J6: L-2-1-1, L-2-1-2, L-2-1-3 | K6: L-2-1-1 도움을 요청하는 대화(가위 주세요./ 여기 있어요.등)를 듣고, 교사의 질문(지금 어떤 도움이 필요하니? 등)에 적절한 답을 한다. L-2-1-2 정보를 묻는 대화(몇 학년 몇 반이에요? /1학년 2반이에요. 등)를 듣고, 안내된 정보를 고른다. L-2-1-3 감정을 나타내는 대화(기분이 어때요? /좋아요. 싫어요. 등)를 듣고, 적절한 감정 그림을 고른다. | L6: ① 낱말·표현 익히기: 가위 주세요, 여기 있어요, 지금 어떤 도움이 필요하니?, 몇 학년 몇 반이에요?, 1학년 2반이에요, 기분이 어때요? ② 도움을 요청하는 대화(가위 주세요./ 여기 있어요.등)를 듣고, 교사의 질문(지금 어떤 도움이 필요하니? 등)에 적절한 답을… ③ 정보를 묻는 대화(몇 학년 몇 반이에요? /1학년 2반이에요. 등)를 듣고, 안내된 정보를 고른다. ④ 확인(진단형) 감정을 나타내는 대화(기분이 어때요? /좋아요. 싫어요. 등)를 듣고, 적절한 감정 그림을 고른다. | M6: 그림·보기 고르기 | N6: 교실 대화 | O6: 말하기-06 | P6: 음성 필요(녹음 파일 권장) / 2인 이상 화자 / 숫자 읽기 확인(예: 10쪽→십 쪽) | Q6: 1 | R6: 예정
A7: 초1~2-듣기-06 | B7: 초1~2 | C7: 듣기 | D7: 2 | E7: 2 | F7: 6 | G7: 선생님의 안내를 듣고 준비해요 | H7: 수업에서 자주 쓰는 간단한 문장을 듣고 이해할 수 있어요. | I7: 수업에서 자주 쓰는 간단한 문장을 듣고 이해할 수 있다. | J7: L-2-2-1 | K7: L-2-2-1 교사의 수업 안내 문장(짝과 말해 보세요, 줄을 그으세요. 등)을 듣고, 해당 행동을 수행한다. | L7: ① 낱말·표현 익히기: 짝과 말해 보세요, 줄을 그으세요 ② 교사의 수업 안내 문장(짝과 말해 보세요, 줄을 그으세요. 등)을 듣고, 해당 행동을 수행한다. ③ 같은 방식, 소재를 바꿔 한 번 더 ④ 확인(진단형 L-2-2-1) | M7: 들은 대로 하기(그림 고르기) | N7: 준비물 | O7: 말하기-08, 읽기-07, 쓰기-08 | P7: 음성 필요(녹음 파일 권장) / 숫자 읽기 확인(예: 10쪽→십 쪽) | Q7: 1 | R7: 예정 | T7: 듣기06과 같은 성취수준(2수준-2). 듣기06이 초3~4용이면 초1~2 판은 소재만 바꿔 제작 가능(진단 발문: 책 12쪽, 자·도화지)
A8: 초1~2-듣기-07 | B8: 초1~2 | C8: 듣기 | D8: 2 | E8: 3 | F8: 7 | G8: 어디에 있는지 듣고 찾아요 | H8: 교실의 사물이나 대상에 관한 간단한 말을 듣고 이해할 수 있어요. | I8: 교실의 사물이나 대상에 관한 간단한 말을 듣고 이해할 수 있다. | J8: L-2-3-1, L-2-3-2 | K8: L-2-3-1 교실 사물의 위치(창문 옆에 있어요. 등)를 듣고, 해당 사물을 손가락으로 가리킨다. L-2-3-2 사물의 색깔이나 크기(빨간 가방, 큰 공책 등)를 듣고, 맞는 사물 그림을 고른다. | L8: ① 낱말·표현 익히기: 창문 옆에 있어요, 빨간 가방, 큰 공책 ② 교실 사물의 위치(창문 옆에 있어요. 등)를 듣고, 해당 사물을 손가락으로 가리킨다. ③ 사물의 색깔이나 크기(빨간 가방, 큰 공책 등)를 듣고, 맞는 사물 그림을 고른다. ④ 확인(진단형 L-2-3-1·L-2-3-2 섞기) | M8: 그림·보기 고르기 | N8: 위치·모양 | P8: 음성 필요(녹음 파일 권장) | Q8: 1 | R8: 예정
A9: 초1~2-듣기-08 | B9: 초1~2 | C9: 듣기 | D9: 2 | E9: 4 | F9: 8 | G9: 천천히 듣고 알맞은 그림을 골라요 | H9: 교사의 느린 발화를 듣고 이해할 수 있어요. | I9: 교사의 느린 발화를 듣고 이해할 수 있다. | J9: L-2-4-1, L-2-4-2, L-2-4-3 | K9: L-2-4-1 천천히 말한 문장(보건실은 1층에 있어요. 등)을 듣고, 문장과 맞는 그림을 고른다. L-2-4-2 천천히 말한 질문(지우개가 어디에 있어요? 등)을 듣고 해당 사물(지우개 등)을 가리킨다. L-2-4-3 천천히 말한 지시(한 줄로 서세요. 등)를 수행한다. | L9: ① 낱말·표현 익히기: 보건실은 1층에 있어요, 지우개가 어디에 있어요?, 지우개, 한 줄로 서세요 ② 천천히 말한 문장(보건실은 1층에 있어요. 등)을 듣고, 문장과 맞는 그림을 고른다. ③ 천천히 말한 질문(지우개가 어디에 있어요? 등)을 듣고 해당 사물(지우개 등)을 가리킨다. ④ 확인(진단형) 천천히 말한 지시(한 줄로 서세요. 등)를 수행한다. | M9: 그림·보기 고르기 / 들은 대로 하기(그림 고르기) | N9: 학교 장소 | O9: 읽기-03 | P9: 음성 필요(녹음 파일 권장) / 숫자 읽기 확인(예: 10쪽→십 쪽) | Q9: 1 | R9: 예정
A10: 초1~2-듣기-09 | B10: 초1~2 | C10: 듣기 | D10: 3 | E10: 1 | F10: 9 | G10: 친구가 좋아하는 것을 알아봐요 | H10: 관심사(좋아하는 것 등)에 관한 대화를 듣고 짐작할 수 있어요. | I10: 관심사(좋아하는 것 등)에 관한 대화를 듣고 짐작할 수 있다. | J10: L-3-1-1, L-3-1-2, L-3-1-3 | K10: L-3-1-1 좋아하는 놀이(공놀이, 줄넘기, 술래잡기 등)에 관한 대화를 듣고, 하고 싶어 하는 놀이를 고른다. L-3-1-2 좋아하는 음식(김밥, 떡볶이, 불고기 등)에 관한 대화를 듣고, 먹고 싶어 하는 음식을 고른다. L-3-1-3 좋아하는 물건(인형, 장난감 등)에 관한 대화를 듣고, 갖고 싶어 하는 물건을 고른다. | L10: ① 낱말·표현 익히기: 공놀이, 줄넘기, 술래잡기, 김밥, 떡볶이, 불고기 ② 좋아하는 놀이(공놀이, 줄넘기, 술래잡기 등)에 관한 대화를 듣고, 하고 싶어 하는 놀이를 고른다. ③ 좋아하는 음식(김밥, 떡볶이, 불고기 등)에 관한 대화를 듣고, 먹고 싶어 하는 음식을 고른다. ④ 확인(진단형) 좋아하는 물건(인형, 장난감 등)에 관한 대화를 듣고, 갖고 싶어 하는 물건을 고른다. | M10: 그림·보기 고르기 | N10: 좋아하는 것 | O10: 말하기-07, 말하기-11, 말하기-14, 쓰기-09 | P10: 음성 필요(녹음 파일 권장) / 2인 이상 화자 | Q10: 3 | R10: 예정
A11: 초1~2-듣기-10 | B11: 초1~2 | C11: 듣기 | D11: 3 | E11: 2 | F11: 10 | G11: 주말 이야기를 듣고 장소를 찾아요 | H11: 겪은 일에 관한 이야기를 듣고 대강의 내용을 이해할 수 있어요. | I11: 겪은 일에 관한 이야기를 듣고 대강의 내용을 이해할 수 있다. | J11: L-3-2-1, L-3-2-2, L-3-2-3 | K11: L-3-2-1 겪은 일에 관한 이야기(주말 지낸 이야기 등)를 듣고, 관련된 장소(공원, 학교, 집 등)를 고른다. L-3-2-2 겪은 일의 순서가 담긴 이야기(여행 등)를 듣고, 장소(공원, 학교, 집 등)를 이야기 순서대로 배열한다. L-3-2-3 겪은 일에 관한 이야기를 듣고, 일치하는 내용을 표시한다. | L11: ① 낱말·표현 익히기: 주말 지낸 이야기, 공원, 학교, 집, 여행 ② 겪은 일에 관한 이야기(주말 지낸 이야기 등)를 듣고, 관련된 장소(공원, 학교, 집 등)를 고른다. ③ 겪은 일의 순서가 담긴 이야기(여행 등)를 듣고, 장소(공원, 학교, 집 등)를 이야기 순서대로 배열한다. ④ 확인(진단형) 겪은 일에 관한 이야기를 듣고, 일치하는 내용을 표시한다. | M11: 그림·보기 고르기 / 순서 놓기(끌어 놓기) / 표시하기(O/X) | N11: 겪은 일 | O11: 듣기-11, 말하기-12, 읽기-09, 쓰기-07, 쓰기-15 | P11: 음성 필요(녹음 파일 권장) / 2인 이상 화자 | Q11: 3 | R11: 예정
A12: 초1~2-듣기-11 | B12: 초1~2 | C12: 듣기 | D12: 3 | E12: 3 | F12: 11 | G12: 그림을 보며 방학 이야기를 들어요 | H12: 단서(그림 등)가 주어진 짧은 이야기를 듣고 내용을 이해할 수 있어요. | I12: 단서(그림 등)가 주어진 짧은 이야기를 듣고 내용을 이해할 수 있다. | J12: L-3-3-1, L-3-3-2 | K12: L-3-3-1 그림을 보며 짧은 이야기(방학동안 한 일 등)를 듣고, 이야기 속 인물과 행동(걸었다, 뛰었다 등)을 연결한다. L-3-3-2 그림을 보며 짧은 이야기(방학 동안 한 일 등)를 듣고, 교사의 질문(방학 동안 무엇을 했나요? 등)에 알맞은 답을 한다. | L12: ① 낱말·표현 익히기: 방학동안 한 일, 걸었다, 뛰었다, 방학 동안 한 일, 방학 동안 무엇을 했나요? ② 그림을 보며 짧은 이야기(방학동안 한 일 등)를 듣고, 이야기 속 인물과 행동(걸었다, 뛰었다 등)을 연결한다. ③ 그림을 보며 짧은 이야기(방학 동안 한 일 등)를 듣고, 교사의 질문(방학 동안 무엇을 했나요? 등)에 알맞은 답을 한다. ④ 확인(진단형 L-3-3-1·L-3-3-2 섞기) | M12: 선 잇기 / 그림·보기 고르기 | N12: 겪은 일 | O12: 듣기-10, 말하기-12, 읽기-09, 쓰기-07, 쓰기-15 | P12: 음성 필요(녹음 파일 권장) | Q12: 3 | R12: 예정
A13: 초1~2-듣기-12 | B13: 초1~2 | C13: 듣기 | D13: 3 | E13: 4 | F13: 12 | G13: 선생님 설명에서 중요한 낱말을 찾아요 | H13: 교사의 발화를 듣고 내용을 부분적으로 이해할 수 있어요. | I13: 교사의 발화를 듣고 내용을 부분적으로 이해할 수 있다. | J13: L-3-4-1, L-3-4-2 | K13: L-3-4-1 교사의 설명(명절 등)을 듣고, 중심 낱말(명절 놀이, 음식 등)을 답한다. L-3-4-2 교사의 안내(현장 체험 학습 준비물 안내 등)을 듣고, 중심 낱말(준비물 중 모자, 도시락 등)을 답한다. | L13: ① 낱말·표현 익히기: 명절, 명절 놀이, 음식, 현장 체험 학습 준비물 안내, 준비물 중 모자, 도시락 ② 교사의 설명(명절 등)을 듣고, 중심 낱말(명절 놀이, 음식 등)을 답한다. ③ 교사의 안내(현장 체험 학습 준비물 안내 등)을 듣고, 중심 낱말(준비물 중 모자, 도시락 등)을 답한다. ④ 확인(진단형 L-3-4-1·L-3-4-2 섞기) | M13: 그림·보기 고르기 | N13: 학교 행사 | O13: 듣기-14, 말하기-17, 읽기-11 | P13: 음성 필요(녹음 파일 권장) | Q13: 3 | R13: 예정
A14: 초1~2-듣기-13 | B14: 초1~2 | C14: 듣기 | D14: 4 | E14: 1 | F14: 13 | G14: 친구 소개를 듣고 알아봐요 | H14: 친숙한 주제의 이야기를 듣고 대강의 내용을 이해할 수 있어요. | I14: 친숙한 주제의 이야기를 듣고 대강의 내용을 이해할 수 있다. | J14: L-4-1-1, L-4-1-2 | K14: L-4-1-1 친숙한 주제(가족 소개, 방과후 활동, 장래희망 등)의 이야기를 듣고, 이야기의 주제를 답한다. L-4-1-2 친숙한 주제(가족 소개, 방과후 활동, 장래희망 등)의 이야기를 듣고, 주요 정보를 답한다. | L14: ① 낱말·표현 익히기: 가족 소개, 방과후 활동, 장래희망 ② 친숙한 주제(가족 소개, 방과후 활동, 장래희망 등)의 이야기를 듣고, 이야기의 주제를 답한다. ③ 친숙한 주제(가족 소개, 방과후 활동, 장래희망 등)의 이야기를 듣고, 주요 정보를 답한다. ④ 확인(진단형 L-4-1-1·L-4-1-2 섞기) | M14: 그림·보기 고르기 | N14: 가족·소개 | O14: 말하기-16, 읽기-10 | P14: 음성 필요(녹음 파일 권장) | Q14: 3 | R14: 예정
A15: 초1~2-듣기-14 | B15: 초1~2 | C15: 듣기 | D15: 4 | E15: 2 | F15: 14 | G15: 안내를 듣고 시간과 장소를 찾아요 | H15: 정보를 알리는 말을 듣고 주요 내용을 찾을 수 있어요. | I15: 정보를 알리는 말을 듣고 주요 내용을 찾을 수 있다. | J15: L-4-2-1, L-4-2-2, L-4-2-3 | K15: L-4-2-1 안내 방송이나 교사의 알림(2시에 도서관으로 오세요. 등)을 듣고, 시간이나 장소를 답한다. L-4-2-2 준비물을 안내하는 말(물감을 들고 오세요. 등)을 듣고 준비해야 할 물건을 고른다. L-4-2-3 학교 행사 안내(체육 대회 등)를 듣고 그에 관한 정보(시간, 장소, 내용 등)를 답한다. | L15: ① 낱말·표현 익히기: 2시에 도서관으로 오세요, 물감을 들고 오세요, 체육 대회, 시간, 장소, 내용 ② 안내 방송이나 교사의 알림(2시에 도서관으로 오세요. 등)을 듣고, 시간이나 장소를 답한다. ③ 준비물을 안내하는 말(물감을 들고 오세요. 등)을 듣고 준비해야 할 물건을 고른다. ④ 확인(진단형) 학교 행사 안내(체육 대회 등)를 듣고 그에 관한 정보(시간, 장소, 내용 등)를 답한다. | M15: 그림·보기 고르기 | N15: 학교 행사 | O15: 듣기-12, 말하기-17, 읽기-11 | P15: 음성 필요(녹음 파일 권장) / 숫자 읽기 확인(예: 10쪽→십 쪽) | Q15: 3 | R15: 예정
A16: 초1~2-듣기-15 | B16: 초1~2 | C16: 듣기 | D16: 4 | E16: 3 | F16: 15 | G16: 친구의 발표를 듣고 답해요 | H16: 이야기나 발표를 듣고 내용을 이해할 수 있어요. | I16: 이야기나 발표를 듣고 내용을 이해할 수 있다. | J16: L-4-3-1, L-4-3-2, L-4-3-3 | K16: L-4-3-1 이야기나 발표(내가 좋아하는 음식, 운동, 사람 등)를 듣고, 발표자가 소개한 대상을 보기에서 고른다. L-4-3-2 이야기나 발표(내가 좋아하는 음식, 운동, 사람 등)를 듣고, 발표 내용과 맞는 그림을 모두 고른다. L-4-3-3 이야기나 발표(내가 좋아하는 음식, 운동, 사람 등)를 듣고, 들은 내용에 대한 사실 질문(무엇에 관한 이야기인가요? 등)에 짧게 답한다. | L16: ① 낱말·표현 익히기: 내가 좋아하는 음식, 운동, 사람, 무엇에 관한 이야기인가요? ② 이야기나 발표(내가 좋아하는 음식, 운동, 사람 등)를 듣고, 발표자가 소개한 대상을 보기에서 고른다. ③ 이야기나 발표(내가 좋아하는 음식, 운동, 사람 등)를 듣고, 발표 내용과 맞는 그림을 모두 고른다. ④ 확인(진단형) 이야기나 발표(내가 좋아하는 음식, 운동, 사람 등)를 듣고, 들은 내용에 대한 사실 질문(무엇에 관한 이… | M16: 그림·보기 고르기 / 여러 개 고르기 | N16: 발표 | O16: 말하기-18 | P16: 음성 필요(녹음 파일 권장) | Q16: 3 | R16: 예정
A17: 초1~2-듣기-16 | B17: 초1~2 | C17: 듣기 | D17: 4 | E17: 4 | F17: 16 | G17: 설명을 듣고 순서대로 해요 | H17: 교사의 발화를 듣고 주요 내용을 이해할 수 있어요. | I17: 교사의 발화를 듣고 주요 내용을 이해할 수 있다. | J17: L-4-4-1, L-4-4-2 | K17: L-4-4-1 교사의 설명(씨앗 심기 과정 등)을 듣고, 일의 순서(흙 담기, 씨앗 심기, 물 주기 등)을 답한다. L-4-4-2 교사의 설명(현장 체험 학습 주의 사항 안내 등)을 듣고, 주요 내용(장소 예절, 안전 등)을 답한다. | L17: ① 낱말·표현 익히기: 씨앗 심기 과정, 흙 담기, 씨앗 심기, 물 주기, 현장 체험 학습 주의 사항 안내, 장소 예절 ② 교사의 설명(씨앗 심기 과정 등)을 듣고, 일의 순서(흙 담기, 씨앗 심기, 물 주기 등)을 답한다. ③ 교사의 설명(현장 체험 학습 주의 사항 안내 등)을 듣고, 주요 내용(장소 예절, 안전 등)을 답한다. ④ 확인(진단형 L-4-4-1·L-4-4-2 섞기) | M17: 순서 놓기(끌어 놓기) / 그림·보기 고르기 | N17: 순서·과정 | O17: 읽기-13 | P17: 음성 필요(녹음 파일 권장) / 숫자 읽기 확인(예: 10쪽→십 쪽) | Q17: 3 | R17: 예정
A18: 초1~2-말하기-01 | B18: 초1~2 | C18: 말하기 | D18: 1 | E18: 1 | F18: 1 | G18: 교실 물건 이름을 말해요 | H18: 주변의 사물/대상에 대해 짧고 쉬운 단어로 말할 수 있어요. | I18: 주변의 사물/대상에 대해 짧고 쉬운 단어로 말할 수 있다. | J18: S-1-1-1, S-1-1-2, S-1-1-3 | K18: S-1-1-1 가리키는 교실 사물(책상, 의자, 칠판 등)의 이름을 한 단어로 말한다. S-1-1-2 그림 카드를 보고 동물 이름(고양이 등)을 말한다. S-1-1-3 자신이 가진 물건의 이름(연필, 지우개 등)을 말한다. | L18: ① 낱말·표현 익히기: 책상, 의자, 칠판, 고양이, 연필, 지우개 ② 가리키는 교실 사물(책상, 의자, 칠판 등)의 이름을 한 단어로 말한다. ③ 그림 카드를 보고 동물 이름(고양이 등)을 말한다. ④ 확인(진단형) 자신이 가진 물건의 이름(연필, 지우개 등)을 말한다. | M18: 상황 보고 말하기(녹음) | N18: 교실 물건 | O18: 듣기-01, 읽기-02, 쓰기-04 | P18: 녹음·다시 듣기(저장 안 함) / 판정은 교사 확인 | Q18: 1 | R18: 예정
A19: 초1~2-말하기-02 | B19: 초1~2 | C19: 말하기 | D19: 1 | E19: 2 | F19: 2 | G19: 친구와 어른에게 인사해요 | H19: 간단한 인사말을 주고받을 수 있어요. | I19: 간단한 인사말을 주고받을 수 있다. | J19: S-1-2-1, S-1-2-2 | K19: S-1-2-1 친구와 만나고 헤어질 때 인사말(안녕, 잘가. 등)을 한다. S-1-2-2 어른과 만나고 헤어질 때 인사말(안녕하세요, 안녕히 계세요. 등)을 한다. | L19: ① 낱말·표현 익히기: 안녕, 잘가, 안녕하세요, 안녕히 계세요 ② 친구와 만나고 헤어질 때 인사말(안녕, 잘가. 등)을 한다. ③ 어른과 만나고 헤어질 때 인사말(안녕하세요, 안녕히 계세요. 등)을 한다. ④ 확인(진단형 S-1-2-1·S-1-2-2 섞기) | M19: 상황 보고 말하기(녹음) | N19: 인사 | O19: 듣기-02 | P19: 녹음·다시 듣기(저장 안 함) / 판정은 교사 확인 | Q19: 1 | R19: 예정
A20: 초1~2-말하기-03 | B20: 초1~2 | C20: 말하기 | D20: 1 | E20: 3 | F20: 3 | G20: 이름과 나이를 말해요 | H20: 교사의 질문에 간단하게 대답할 수 있어요. | I20: 교사의 질문에 간단하게 대답할 수 있다. | J20: S-1-3-1, S-1-3-2, S-1-3-3 | K20: S-1-3-1 이름을 묻는 질문(이름이 뭐예요? 등)에 자신의 이름(저는 ○○예요. 등)을 말한다. S-1-3-2 나이를 묻는 질문(몇 살이예요? 등)에 숫자나 짧은 문장(8, 여덟 살이에요. 등)으로 답한다. S-1-3-3 물건의 이름을 묻는 질문(이것은 뭐예요? 등) 에 한 단어(연필이에요. 등)로 답한다. | L20: ① 낱말·표현 익히기: 이름이 뭐예요?, 저는 ○○예요, 몇 살이예요?, 8, 여덟 살이에요, 이것은 뭐예요? ② 이름을 묻는 질문(이름이 뭐예요? 등)에 자신의 이름(저는 ○○예요. 등)을 말한다. ③ 나이를 묻는 질문(몇 살이예요? 등)에 숫자나 짧은 문장(8, 여덟 살이에요. 등)으로 답한다. ④ 확인(진단형) 물건의 이름을 묻는 질문(이것은 뭐예요? 등) 에 한 단어(연필이에요. 등)로 답한다. | M20: 상황 보고 말하기(녹음) | N20: 자기소개 | O20: 쓰기-03 | P20: 녹음·다시 듣기(저장 안 함) / 판정은 교사 확인 | Q20: 1 | R20: 예정
... A29: 초1~2-말하기-12 | B29: 초1~2 | C29: 말하기 | D29: 3 | E29: 2 | F29: 12 | G29: 주말에 한 일을 말해요 | H29: 일상생활에서 겪은 일에 관해 말할 수 있어요. | I29: 일상생활에서 겪은 일에 관해 말할 수 있다. | J29: S-3-2-1, S-3-2-2, S-3-2-3 | K29: S-3-2-1 겪은 일(가족 여행, 주말 지낸 이야기 등)을 시간 표현(어제, 오늘 등)을 사용해 말한다. S-3-2-2 겪은 일(가족 여행, 주말 지낸 이야기 등)에 나온 사람이나 장소를 포함해 말한다. S-3-2-3 겪은 일(가족 여행, 주말 지낸 이야기 등)에 대한 느낌을 한 문장으로 말한다. | L29: ① 낱말·표현 익히기: 가족 여행, 주말 지낸 이야기, 어제, 오늘 ② 겪은 일(가족 여행, 주말 지낸 이야기 등)을 시간 표현(어제, 오늘 등)을 사용해 말한다. ③ 겪은 일(가족 여행, 주말 지낸 이야기 등)에 나온 사람이나 장소를 포함해 말한다. ④ 확인(진단형) 겪은 일(가족 여행, 주말 지낸 이야기 등)에 대한 느낌을 한 문장으로 말한다. | M29: 상황 보고 말하기(녹음) | N29: 겪은 일 | O29: 듣기-10, 듣기-11, 읽기-09, 쓰기-07, 쓰기-15 | P29: 녹음·다시 듣기(저장 안 함) / 판정은 교사 확인 | Q29: 3 | R29: 예정
A30: 초1~2-말하기-13 | B30: 초1~2 | C30: 말하기 | D30: 3 | E30: 3 | F30: 13 | G30: 수업 시간에 묻고 답해요 | H30: 수업에 참여하여 간단하게 질문하고 대답할 수 있어요. | I30: 수업에 참여하여 간단하게 질문하고 대답할 수 있다. | J30: S-3-3-1, S-3-3-2 | K30: S-3-3-1 수업 내용 중 모르는 낱말(교과 어휘: 모양, 가구, 분리수거 등)을 질문한다. S-3-3-2 교사의 확인 질문(어떤 모양이 있나요? 등)에 수업 내용과 관련된 말(동그라미 모양이 있어요. 등)로 답한다. | L30: ① 낱말·표현 익히기: 교과 어휘: 모양, 가구, 분리수거, 어떤 모양이 있나요?, 동그라미 모양이 있어요 ② 수업 내용 중 모르는 낱말(교과 어휘: 모양, 가구, 분리수거 등)을 질문한다. ③ 교사의 확인 질문(어떤 모양이 있나요? 등)에 수업 내용과 관련된 말(동그라미 모양이 있어요. 등)로 답한다. ④ 확인(진단형 S-3-3-1·S-3-3-2 섞기) | M30: 질문 만들어 말하기(녹음) / 상황 보고 말하기(녹음) | N30: 수업 참여 | P30: 녹음·다시 듣기(저장 안 함) / 판정은 교사 확인 | Q30: 3 | R30: 예정
A31: 초1~2-말하기-14 | B31: 초1~2 | C31: 말하기 | D31: 3 | E31: 4 | F31: 14 | G31: 친구와 짧게 이야기해요 | H31: 간단한 문장을 활용하여 짧은 대화에 참여할 수 있어요. | I31: 간단한 문장을 활용하여 짧은 대화에 참여할 수 있다. | J31: S-3-4-1, S-3-4-2 | K31: S-3-4-1 좋아하는 것에 관한 대화(딱지치기 할 줄 알아?/ 나 할 줄 알아. 등)를 한다. S-3-4-2 상대의 말(난 짜장면을 좋아해. 너는 뭘 좋아해? 등)을 듣고 그 말에 맞는 반응(나는 김밥을 좋아해. 등)을 한 문장으로 말한다. | L31: ① 낱말·표현 익히기: 딱지치기 할 줄 알아?, 나 할 줄 알아, 난 짜장면을 좋아해, 너는 뭘 좋아해?, 나는 김밥을 좋아해 ② 좋아하는 것에 관한 대화(딱지치기 할 줄 알아?/ 나 할 줄 알아. 등)를 한다. ③ 상대의 말(난 짜장면을 좋아해. 너는 뭘 좋아해? 등)을 듣고 그 말에 맞는 반응(나는 김밥을 좋아해. 등)을 한 문장으로 … ④ 확인(진단형 S-3-4-1·S-3-4-2 섞기) | M31: 역할 대화(녹음) / 상황 보고 말하기(녹음) | N31: 좋아하는 것 | O31: 듣기-09, 말하기-07, 말하기-11, 쓰기-09 | P31: 녹음·다시 듣기(저장 안 함) / 판정은 교사 확인 | Q31: 3 | R31: 예정
A32: 초1~2-말하기-15 | B32: 초1~2 | C32: 말하기 | D32: 3 | E32: 5 | F32: 15 | G32: 비슷한 소리를 구별해서 말해요 | H32: 비교적 정확한 발음으로 말할 수 있어요. | I32: 비교적 정확한 발음으로 말할 수 있다. | J32: S-3-5-1, S-3-5-2, S-3-5-3 | K32: S-3-5-1 제시한 낱말(발-팔, 볼-벌, 달-딸 등)을 구별되게 발음한다. S-3-5-2 문장을 말할 때 의미 단위로 끊어 말한다.(키가 크고 눈이 커요. , 도서관에 가서 책을 읽어요. 등) S-3-5-3 상대가 알아듣기 어려워하면 발음이나 속도를 고쳐 다시 말한다. | L32: ① 낱말·표현 익히기: 발-팔, 볼-벌, 달-딸, 키가 크고 눈이 커요, 도서관에 가서 책을 읽어요 ② 제시한 낱말(발-팔, 볼-벌, 달-딸 등)을 구별되게 발음한다. ③ 문장을 말할 때 의미 단위로 끊어 말한다.(키가 크고 눈이 커요. , 도서관에 가서 책을 읽어요. 등) ④ 확인(진단형) 상대가 알아듣기 어려워하면 발음이나 속도를 고쳐 다시 말한다. | M32: 따라 말하기(녹음 비교) / 상황 보고 말하기(녹음) | N32: 발음 | O32: 말하기-05, 말하기-10 | P32: 녹음·다시 듣기(저장 안 함) / 판정은 교사 확인 / 모범 발음 녹음 | Q32: 3 | R32: 예정
A33: 초1~2-말하기-16 | B33: 초1~2 | C33: 말하기 | D33: 4 | E33: 1 | F33: 16 | G33: 가족과 친구를 소개해요 | H33: 친숙한 주제에 관해 간단하게 말할 수 있어요. | I33: 친숙한 주제에 관해 간단하게 말할 수 있다. | J33: S-4-1-1, S-4-1-2 | K33: S-4-1-1 친숙한 주제(가족 소개, 친구 소개, 방과후 활동, 장래희망 등)에 관해 소개나 발표를 한다. S-4-1-2 그림이나 사진(운동 경기 사진, 장소 사진, 날씨 사진, 자연 사진 등)을 보며 관련된 정보를 두 가지 이상 말한다. | L33: ① 낱말·표현 익히기: 가족 소개, 친구 소개, 방과후 활동, 장래희망, 운동 경기 사진, 장소 사진 ② 친숙한 주제(가족 소개, 친구 소개, 방과후 활동, 장래희망 등)에 관해 소개나 발표를 한다. ③ 그림이나 사진(운동 경기 사진, 장소 사진, 날씨 사진, 자연 사진 등)을 보며 관련된 정보를 두 가지 이상 말한다. ④ 확인(진단형 S-4-1-1·S-4-1-2 섞기) | M33: 발표 틀 채워 말하기(녹음) / 상황 보고 말하기(녹음) | N33: 가족·소개 | O33: 듣기-13, 읽기-10 | P33: 녹음·다시 듣기(저장 안 함) / 판정은 교사 확인 | Q33: 3 | R33: 예정
A34: 초1~2-말하기-17 | B34: 초1~2 | C34: 말하기 | D34: 4 | E34: 2 | F34: 17 | G34: 친구들에게 준비물을 알려 줘요 | H34: 친구들에게 정보를 알리는 말을 할 수 있어요. | I34: 친구들에게 정보를 알리는 말을 할 수 있다. | J34: S-4-2-1, S-4-2-2, S-4-2-3 | K34: S-4-2-1 학교 생활(학급 활동, 운동회, 현장체험학습 등)에 필요한 준비물(도시락, 물, 모자, 필기 도구 등)을 친구에게 알린다. S-4-2-2 친구에게 학교 생활에 관한 내용(시간표, 식단표, 숙제 등)을 알린다. S-4-2-3 친구에게 일상생활에서 지켜야 할 내용(공공장소 예절, 학급 규칙, 교통 규칙 등)을 알린다. | L34: ① 낱말·표현 익히기: 학급 활동, 운동회, 현장체험학습, 도시락, 물, 모자 ② 학교 생활(학급 활동, 운동회, 현장체험학습 등)에 필요한 준비물(도시락, 물, 모자, 필기 도구 등)을 친구에게 알린다. ③ 친구에게 학교 생활에 관한 내용(시간표, 식단표, 숙제 등)을 알린다. ④ 확인(진단형) 친구에게 일상생활에서 지켜야 할 내용(공공장소 예절, 학급 규칙, 교통 규칙 등)을 알린다. | M34: 상황 보고 말하기(녹음) | N34: 학교 행사 | O34: 듣기-12, 듣기-14, 읽기-11 | P34: 녹음·다시 듣기(저장 안 함) / 판정은 교사 확인 | Q34: 3 | R34: 예정
A35: 초1~2-말하기-18 | B35: 초1~2 | C35: 말하기 | D35: 4 | E35: 3 | F35: 18 | G35: 내 생각을 발표해요 | H35: 수업에서 자신의 생각을 간단하게 말할 수 있어요. | I35: 수업에서 자신의 생각을 간단하게 말할 수 있다. | J35: S-4-3-1, S-4-3-2, S-4-3-3 | K35: S-4-3-1 수업 주제에 대해 발표( “제 생각은 ○○입니다.” 등)의 형태로 자신의 생각을 말한다. S-4-3-2 이유나 근거를 들어 발표(“왜냐하면 ○○이기 때문입니다.” 등)의 형태로 자신의 생각을 말한다. S-4-3-3 그림이나 이야기 속 인물의 행동에 대해 자신의 생각("제 생각에 ○○이/가 거짓말을 말한 것은 나쁘다고 생각합니다." 등)을 말한다. | L35: ① 낱말·표현 익히기: “제 생각은 ○○입니다.”, “왜냐하면 ○○이기 때문입니다.”, "제 생각에 ○○이 ② 수업 주제에 대해 발표( “제 생각은 ○○입니다.” 등)의 형태로 자신의 생각을 말한다. ③ 이유나 근거를 들어 발표(“왜냐하면 ○○이기 때문입니다.” 등)의 형태로 자신의 생각을 말한다. ④ 확인(진단형) 그림이나 이야기 속 인물의 행동에 대해 자신의 생각("제 생각에 ○○이/가 거짓말을 말한 것은 나쁘다고 생… | M35: 발표 틀 채워 말하기(녹음) / 상황 보고 말하기(녹음) | N35: 발표 | O35: 듣기-15 | P35: 녹음·다시 듣기(저장 안 함) / 판정은 교사 확인 | Q35: 3 | R35: 예정
A36: 초1~2-말하기-19 | B36: 초1~2 | C36: 말하기 | D36: 4 | E36: 4 | F36: 19 | G36: 이야기를 주고받으며 대화해요 | H36: 다소 긴 대화에 자연스럽게 참여할 수 있어요. | I36: 다소 긴 대화에 자연스럽게 참여할 수 있다. | J36: S-4-4-1, S-4-4-2, S-4-4-3 | K36: S-4-4-1 주제(자연 환경, 놀이, 명절, 수업 등)에 관한 대화에서 질문과 대답을 두 차례 이상 주고받는다. S-4-4-2 상대의 말을 듣고 맞장구(맞아, 나도 그래. 등)나 확인 표현(정말 그랬어? 등)을 사용한다. S-4-4-3 대화 중 모르는 말을 들으면 되묻거나 설명(○○이 무슨 뜻이야? / ○○는 이런 뜻이야. 등)한다. | L36: ① 낱말·표현 익히기: 자연 환경, 놀이, 명절, 수업, 맞아, 나도 그래 ② 주제(자연 환경, 놀이, 명절, 수업 등)에 관한 대화에서 질문과 대답을 두 차례 이상 주고받는다. ③ 상대의 말을 듣고 맞장구(맞아, 나도 그래. 등)나 확인 표현(정말 그랬어? 등)을 사용한다. ④ 확인(진단형) 대화 중 모르는 말을 들으면 되묻거나 설명(○○이 무슨 뜻이야? / ○○는 이런 뜻이야. 등)한다. | M36: 역할 대화(녹음) | N36: 대화 | P36: 녹음·다시 듣기(저장 안 함) / 판정은 교사 확인 | Q36: 3 | R36: 예정
A37: 초1~2-말하기-20 | B37: 초1~2 | C37: 말하기 | D37: 4 | E37: 5 | F37: 20 | G37: 상대에 맞게 높임말을 써요 | H37: 대화 상대를 고려하여 어느 정도 자연스럽게 말할 수 있어요. | I37: 대화 상대를 고려하여 어느 정도 자연스럽게 말할 수 있다. | J37: S-4-5-1, S-4-5-2, S-4-5-3 | K37: S-4-5-1 대상에 따라 높임말, 평어 (“~주세요.”, “~해 주세요.” , "괜찮아?, 같이 하자." 등)을 사용하여 말한다. S-4-5-2 상황(고마운 상황, 미안한 상황 등)에 따라 알맞은 표현을 사용한다. S-4-5-3 발표나 대화에서 상대가 들을 수 있는 크기와 속도로 말한다. | L37: ① 낱말·표현 익히기: “~주세요.”, “~해 주세요.”, "괜찮아?, 같이 하자.", 고마운 상황, 미안한 상황 ② 대상에 따라 높임말, 평어 (“~주세요.”, “~해 주세요.” , "괜찮아?, 같이 하자." 등)을 사용하여 말한다. ③ 상황(고마운 상황, 미안한 상황 등)에 따라 알맞은 표현을 사용한다. ④ 확인(진단형) 발표나 대화에서 상대가 들을 수 있는 크기와 속도로 말한다. | M37: 상황 보고 말하기(녹음) / 따라 말하기(녹음 비교) | N37: 높임말 | P37: 녹음·다시 듣기(저장 안 함) / 판정은 교사 확인 / 모범 발음 녹음 | Q37: 3 | R37: 예정
A38: 초1~2-읽기-01 | B38: 초1~2 | C38: 읽기 | D38: 1 | E38: 1 | F38: 1 | G38: 글자와 낱말을 소리 내어 읽어요 | H38: 글자와 단어를 소리 내어 읽을 수 있어요. | I38: 글자와 단어를 소리 내어 읽을 수 있다. | J38: R-1-1-1, R-1-1-2, R-1-1-3 | K38: R-1-1-1 자음과 모음이 결합된 글자(가, 나, 모, 수 등)를 보고 소리 내어 읽는다. R-1-1-2 그림과 함께 제시된 낱말(사과, 우유, 학교 등)을 보고 소리 내어 읽는다. R-1-1-3 교실에서 자주 보는 낱말(학교, 교실 등)을 보고 소리 내어 읽는다. | L38: ① 낱말·표현 익히기: 가, 나, 모, 수, 사과, 우유 ② 자음과 모음이 결합된 글자(가, 나, 모, 수 등)를 보고 소리 내어 읽는다. ③ 그림과 함께 제시된 낱말(사과, 우유, 학교 등)을 보고 소리 내어 읽는다. ④ 확인(진단형) 교실에서 자주 보는 낱말(학교, 교실 등)을 보고 소리 내어 읽는다. | M38: 따라 읽기(녹음) | N38: 한글 자모 | O38: 듣기-04, 읽기-04, 쓰기-01, 쓰기-02 | P38: 따라 읽기 녹음 / 낱말 음성 | Q38: 2 | R38: 예정
A39: 초1~2-읽기-02 | B39: 초1~2 | C39: 읽기 | D39: 1 | E39: 2 | F39: 2 | G39: 낱말을 읽고 그림과 연결해요 | H39: 짧고 쉬운 단어를 읽고 의미를 이해할 수 있어요. | I39: 짧고 쉬운 단어를 읽고 의미를 이해할 수 있다. | J39: R-1-2-1, R-1-2-2 | K39: R-1-2-1 낱말 카드(가방, 우유, 강아지 등)를 읽고 해당하는 그림이나 실물을 연결한다. R-1-2-2 교실 물건 이름(책상, 의자, 문 등)을 읽고 해당 물건에 사물 이름표를 붙인다. | L39: ① 낱말·표현 익히기: 가방, 우유, 강아지, 책상, 의자, 문 ② 낱말 카드(가방, 우유, 강아지 등)를 읽고 해당하는 그림이나 실물을 연결한다. ③ 교실 물건 이름(책상, 의자, 문 등)을 읽고 해당 물건에 사물 이름표를 붙인다. ④ 확인(진단형 R-1-2-1·R-1-2-2 섞기) | M39: 선 잇기·이름표 붙이기 | N39: 교실 물건 | O39: 듣기-01, 말하기-01, 쓰기-04 | P39: 낱말 음성 | Q39: 2 | R39: 예정
A40: 초1~2-읽기-03 | B40: 초1~2 | C40: 읽기 | D40: 1 | E40: 3 | F40: 3 | G40: 학교 안내판을 읽어요 | H40: 생활에서 사용하는 간단한 안내/간판 등을 이해할 수 있어요. | I40: 생활에서 사용하는 간단한 안내/간판 등을 이해할 수 있다. | J40: R-1-3-1, R-1-3-2, R-1-3-3 | K40: R-1-3-1 표지판, 간판에 쓰여진 어휘(약국, 병원, 보건실, 화장실 등)를 읽고 해당 장소를 가리키거나 이동한다. R-1-3-2 생활 규칙 안내(줄 서기, 손 씻기 등)를 읽고 해야 할 행동을 짧은 말이나 몸짓으로 나타낸다. R-1-3-3 신발장, 책상, 사물함 등에 붙은 이름표를 읽고 자신의 자리를 찾는다. | L40: ① 낱말·표현 익히기: 약국, 병원, 보건실, 화장실, 줄 서기, 손 씻기 ② 표지판, 간판에 쓰여진 어휘(약국, 병원, 보건실, 화장실 등)를 읽고 해당 장소를 가리키거나 이동한다. ③ 생활 규칙 안내(줄 서기, 손 씻기 등)를 읽고 해야 할 행동을 짧은 말이나 몸짓으로 나타낸다. ④ 확인(진단형) 신발장, 책상, 사물함 등에 붙은 이름표를 읽고 자신의 자리를 찾는다. | M40: 읽고 하기(그림 고르기) / 순서 놓기(끌어 놓기) / 선 잇기·이름표 붙이기 | N40: 학교 장소 | O40: 듣기-08 | P40: 낱말 음성 | Q40: 2 | R40: 예정
A41: 초1~2-읽기-04 | B41: 초1~2 | C41: 읽기 | D41: 1 | E41: 4 | F41: 4 | G41: 받침을 살펴 바르게 읽어요 | H41: 한글 자음과 모음, 받침 등 글자를 식별하여 읽을 수 있어요. | I41: 한글 자음과 모음, 받침 등 글자를 식별하여 읽을 수 있다. | J41: R-1-4-1, R-1-4-2, R-1-4-3 | K41: R-1-4-1 그림(오리 등)을 보고 알맞은 모음(오리, 우리 중 고르기)이 들어간 글자를 골라 읽는다. R-1-4-2 그림(사과 등)을 보고 알맞은 자음(사과, 자과 중 고르기)이 들어간 글자를 골라 읽는다. R-1-4-3 그림(물병 등)을 보고 알맞은 받침(물병, 문병 중 고르기)이 들어간 글자를 골라 읽는다. | L41: ① 낱말·표현 익히기: 오리, 우리 중 고르기, 사과, 자과 중 고르기, 물병, 문병 중 고르기 ② 그림(오리 등)을 보고 알맞은 모음(오리, 우리 중 고르기)이 들어간 글자를 골라 읽는다. ③ 그림(사과 등)을 보고 알맞은 자음(사과, 자과 중 고르기)이 들어간 글자를 골라 읽는다. ④ 확인(진단형) 그림(물병 등)을 보고 알맞은 받침(물병, 문병 중 고르기)이 들어간 글자를 골라 읽는다. | M41: 따라 읽기(녹음) | N41: 한글 자모 | O41: 듣기-04, 읽기-01, 쓰기-01, 쓰기-02 | P41: 따라 읽기 녹음 / 낱말 음성 | Q41: 2 | R41: 예정
A42: 초1~2-읽기-05 | B42: 초1~2 | C42: 읽기 | D42: 2 | E42: 1 | F42: 5 | G42: 띄어서 문장을 읽어요 | H42: 문장을 알맞게 띄어 읽을 수 있어요. | I42: 문장을 알맞게 띄어 읽을 수 있다. | J42: R-2-1-1, R-2-1-2 | K42: R-2-1-1 표시한 쉬는 곳(나는 v 학교에 v 가요. 등)에 맞추어 짧은 문장을 띄어 읽는다. R-2-1-2 두세 어절로 된 짧은 문장(우유를 마셔요. 운동장에서 놀아요. 집에서 숙제를 해요. 등)을 낱말 사이에서 띄어 읽는다. | L42: ① 낱말·표현 익히기: 나는 v 학교에 v 가요, 우유를 마셔요, 운동장에서 놀아요, 집에서 숙제를 해요 ② 표시한 쉬는 곳(나는 v 학교에 v 가요. 등)에 맞추어 짧은 문장을 띄어 읽는다. ③ 두세 어절로 된 짧은 문장(우유를 마셔요. 운동장에서 놀아요. 집에서 숙제를 해요. 등)을 낱말 사이에서 띄어 읽는다. ④ 확인(진단형 R-2-1-1·R-2-1-2 섞기) | M42: 선 잇기·이름표 붙이기 / 끊어 읽기 표시(v 넣기) | N42: 문장 | O42: 읽기-08, 쓰기-05, 쓰기-10, 쓰기-14 | P42: 따라 읽기 녹음 / 지문 읽어 주기 선택 | Q42: 2 | R42: 예정
A43: 초1~2-읽기-06 | B43: 초1~2 | C43: 읽기 | D43: 2 | E43: 2 | F43: 6 | G43: 문장을 읽고 알맞게 행동해요 | H43: 문장의 의미를 대강 이해할 수 있어요. | I43: 문장의 의미를 대강 이해할 수 있다. | J43: R-2-2-1, R-2-2-2 | K43: R-2-2-1 짧은 지시문(문을 닫아요. 문을 열어요. 등)을 읽고 문장에 맞는 행동을 한다. R-2-2-2 짧은 문장(고양이가 자요. 아이가 뛰어요. 민수가 공을 차요. 등)을 읽고 문장 내용과 맞는 그림을 연결한다. | L43: ① 낱말·표현 익히기: 문을 닫아요, 문을 열어요, 고양이가 자요, 아이가 뛰어요, 민수가 공을 차요 ② 짧은 지시문(문을 닫아요. 문을 열어요. 등)을 읽고 문장에 맞는 행동을 한다. ③ 짧은 문장(고양이가 자요. 아이가 뛰어요. 민수가 공을 차요. 등)을 읽고 문장 내용과 맞는 그림을 연결한다. ④ 확인(진단형 R-2-2-1·R-2-2-2 섞기) | M43: 읽고 하기(그림 고르기) / 선 잇기·이름표 붙이기 | N43: 교실 지시 | O43: 듣기-03 | P43: 지문 읽어 주기 선택 | Q43: 2 | R43: 예정
A44: 초1~2-읽기-07 | B44: 초1~2 | C44: 읽기 | D44: 2 | E44: 3 | F44: 7 | G44: 알림장을 읽고 준비물을 찾아요 | H44: 알림장, 게시판 등의 글을 읽고 정보를 찾을 수 있어요. | I44: 알림장, 게시판 등의 글을 읽고 정보를 찾을 수 있다. | J44: R-2-3-1, R-2-3-2 | K44: R-2-3-1 알림장(준비물: 색종이와 가위 가져오기 등)을 읽고 필요한 준비물(색종이, 가위 등)을 고른다. R-2-3-2 게시판 안내문(도서관에서 퀴즈 행사를 합니다. 등)에서 필요한 정보(장소, 일시, 대상 등)에 동그라미를 한다. | L44: ① 낱말·표현 익히기: 준비물: 색종이와 가위 가져오기, 색종이, 가위, 도서관에서 퀴즈 행사를 합니다, 장소, 일시 ② 알림장(준비물: 색종이와 가위 가져오기 등)을 읽고 필요한 준비물(색종이, 가위 등)을 고른다. ③ 게시판 안내문(도서관에서 퀴즈 행사를 합니다. 등)에서 필요한 정보(장소, 일시, 대상 등)에 동그라미를 한다. ④ 확인(진단형 R-2-3-1·R-2-3-2 섞기) | M44: 읽고 보기 고르기 / 문장·낱말 표시하기 | N44: 준비물 | O44: 듣기-06, 말하기-08, 쓰기-08 | P44: 지문 읽어 주기 선택 | Q44: 2 | R44: 예정
A45: 초1~2-읽기-08 | B45: 초1~2 | C45: 읽기 | D45: 2 | E45: 4 | F45: 8 | G45: 뜻을 생각하며 끊어 읽어요 | H45: 문장을 의미 단위로 끊어 읽을 수 있어요. | I45: 문장을 의미 단위로 끊어 읽을 수 있다. | J45: R-2-4-1, R-2-4-2 | K45: R-2-4-1 누가 무엇을 하는지 드러나도록 짧은 문장(지아가 v그림을 그려요. 등)을 두 부분으로 나누어 읽는다. R-2-4-2 장소나 시간을 나타내는 말(운동장에서 v 친구와 놀아요. 아침에 v 학교에 가요. 등)을 앞부분에서 쉬어 읽는다. | L45: ① 낱말·표현 익히기: 지아가 v그림을 그려요, 운동장에서 v 친구와 놀아요, 아침에 v 학교에 가요 ② 누가 무엇을 하는지 드러나도록 짧은 문장(지아가 v그림을 그려요. 등)을 두 부분으로 나누어 읽는다. ③ 장소나 시간을 나타내는 말(운동장에서 v 친구와 놀아요. 아침에 v 학교에 가요. 등)을 앞부분에서 쉬어 읽는다. ④ 확인(진단형 R-2-4-1·R-2-4-2 섞기) | M45: 선 잇기·이름표 붙이기 | N45: 문장 | O45: 읽기-05, 쓰기-05, 쓰기-10, 쓰기-14 | P45: 따라 읽기 녹음 / 지문 읽어 주기 선택 | Q45: 2 | R45: 예정
A46: 초1~2-읽기-09 | B46: 초1~2 | C46: 읽기 | D46: 3 | E46: 1 | F46: 9 | G46: 짧은 글에서 누가, 어디에서를 찾아요 | H46: 쉽고 짧은 글을 읽고 대강의 내용을 이해할 수 있어요. | I46: 쉽고 짧은 글을 읽고 대강의 내용을 이해할 수 있다. | J46: R-3-1-1, R-3-1-2, R-3-1-3, R-3-1-4 | K46: R-3-1-1 두세 문장으로 된 이야기를 읽고 등장인물을 표시한다. R-3-1-2 짧은 글을 읽고 일이 일어난 장소를 표시한다. R-3-1-3 짧은 글을 읽고 글에서 등장인물이 한 일을 고른다. R-3-1-4 짧은 글을 읽고 내용과 맞는 그림을 고른다. | L46: ① 낱말·표현 익히기: 핵심 낱말 ② 두세 문장으로 된 이야기를 읽고 등장인물을 표시한다. ③ 짧은 글을 읽고 일이 일어난 장소를 표시한다. ④ 확인(진단형) 짧은 글을 읽고 글에서 등장인물이 한 일을 고른다. | M46: 문장·낱말 표시하기 / 읽고 보기 고르기 | N46: 겪은 일 | O46: 듣기-10, 듣기-11, 말하기-12, 쓰기-07, 쓰기-15 | P46: 지문 읽어 주기 선택 | Q46: 3 | R46: 예정
A47: 초1~2-읽기-10 | B47: 초1~2 | C47: 읽기 | D47: 3 | E47: 2 | F47: 10 | G47: 소개하는 글을 읽어요 | H47: 소개하는 글을 읽고 주요 내용을 찾을 수 있어요. | I47: 소개하는 글을 읽고 주요 내용을 찾을 수 있다. | J47: R-3-2-1, R-3-2-2, R-3-2-3 | K47: R-3-2-1 친구 소개 글을 읽고 친구의 특징(옷차림, 생김새 등)에 알맞은 그림을 고른다. R-3-2-2 학교 소개 글을 읽고 주요 정보(교화, 교목 등)를 찾는다. R-3-2-3 좋아하는 동물 소개 글을 읽고 동물의 특징(색깔, 다리 수, 사는 곳 등)에 관한 질문에 답한다. | L47: ① 낱말·표현 익히기: 옷차림, 생김새, 교화, 교목, 색깔, 다리 수 ② 친구 소개 글을 읽고 친구의 특징(옷차림, 생김새 등)에 알맞은 그림을 고른다. ③ 학교 소개 글을 읽고 주요 정보(교화, 교목 등)를 찾는다. ④ 확인(진단형) 좋아하는 동물 소개 글을 읽고 동물의 특징(색깔, 다리 수, 사는 곳 등)에 관한 질문에 답한다. | M47: 읽고 보기 고르기 | N47: 가족·소개 | O47: 듣기-13, 말하기-16 | P47: 지문 읽어 주기 선택 | Q47: 3 | R47: 예정
A48: 초1~2-읽기-11 | B48: 초1~2 | C48: 읽기 | D48: 3 | E48: 3 | F48: 11 | G48: 초대 글과 안내 글을 읽어요 | H48: 다양한 종류의 짧고 쉬운 글의 내용을 이해할 수 있어요. | I48: 다양한 종류의 짧고 쉬운 글의 내용을 이해할 수 있다. | J48: R-3-3-1, R-3-3-2, R-3-3-3, R-3-3-4 | K48: R-3-3-1 짧은 초대 글을 읽고 초대의 목적이나 의도를 찾아낸다. R-3-3-2 간단한 메세지를 읽고 부탁한 일을 문장으로 답한다. R-3-3-3 짧은 안내 글(도서관 이용방법, 학교 규칙 등)을 읽고 해야 할 행동을 찾는다. R-3-3-4 짧은 글(생활문, 설명하는 글, 의견을 나타내는 글 등)을 읽고 글의 주제에 관련한 문장에 표시한다. | L48: ① 낱말·표현 익히기: 도서관 이용방법, 학교 규칙, 생활문, 설명하는 글, 의견을 나타내는 글 ② 짧은 초대 글을 읽고 초대의 목적이나 의도를 찾아낸다. ③ 간단한 메세지를 읽고 부탁한 일을 문장으로 답한다. ④ 확인(진단형) 짧은 안내 글(도서관 이용방법, 학교 규칙 등)을 읽고 해야 할 행동을 찾는다. | M48: 읽고 보기 고르기 / 읽고 하기(그림 고르기) / 문장·낱말 표시하기 | N48: 학교 행사 | O48: 듣기-12, 듣기-14, 말하기-17 | P48: 지문 읽어 주기 선택 | Q48: 3 | R48: 예정
...

Sheet 진단 문항
A1: 학년군 | B1: 영역 | C1: 수준 | D1: 성취수준 | E1: 문항 | F1: 코드 | G1: 차시 ID | H1: 성취수준(원문) | I1: 체크리스트 문항 | J1: 교사 발문·절차 | K1: 학생 수행
A2: 초1~2 | B2: 듣기 | C2: 1 | D2: 1 | E2: 1 | F2: L-1-1-1 | G2: 초1~2-듣기-01 | H2: 짧고 쉬운 단어를 듣고 대상을 찾을 수 있다. | I2: 교사가 교실 사물(연필, 지우개, 공책 등의 학용품 등)을 말하면, 해당 사물을 가리킨다. | J2: (연필, 지우개, 공책 등 학용품 그림 카드나 실물을 학생 앞에 늘어놓고) “연필“, “지우개“, “공책”이라고 한 단어씩 천천히 말한다. | K2: 교사가 말한 학용품의 그림이나 실물을 손가락으로 가리키거나 집어 든다. 연필 지우개 공책
A3: 초1~2 | B3: 듣기 | C3: 1 | D3: 1 | E3: 2 | F3: L-1-1-2 | G3: 초1~2-듣기-01 | H3: 짧고 쉬운 단어를 듣고 대상을 찾을 수 있다. | I3: 교사가 음식 이름(사과, 포도, 우유 등)을 말하면, 해당 사물을 가리킨다. | J3: (사과, 포도, 우유 등 음식 그림 카드나 실물 모형을 펼쳐 놓고) “사과“, “포도“, “우유“라고 한 단어씩 천천히 말한다. | K3: 교사가 말한 음식의 그림이나 모형을 손가락으로 가리키거나 집어 든다. 사과 포도 우유
A4: 초1~2 | B4: 듣기 | C4: 1 | D4: 1 | E4: 3 | F4: L-1-1-3 | G4: 초1~2-듣기-01 | H4: 짧고 쉬운 단어를 듣고 대상을 찾을 수 있다. | I4: 교사가 생활 용품(모자, 가방, 책상, 의자 등)을 말하면, 해당 사물을 가리킨다. | J4: (모자, 가방, 책상, 의자 등 생활 용품 그림 카드나 실물을 보여 주고) “모자“, “가방“, “책상“, “의자“라고 한 단어씩 천천히 말한다. | K4: 교사가 말한 생활 용품의 그림이나 실물을 손가락으로 가리킨다. 모자 가방 책상 의자
A5: 초1~2 | B5: 듣기 | C5: 1 | D5: 2 | E5: 1 | F5: L-1-2-1 | G5: 초1~2-듣기-02 | H5: 간단한 인사말을 듣고 이해할 수 있다. | I5: 만나고 헤어질 때 인사말(안녕하세요, 안녕히 계세요 등)에 답한다. | J5: 학생을 만났을 때 상황으로 다음 인사말 중 하나를 한다. ① “안녕하세요?“ ② “만나서 반가워요.“ | K5: 교사의 인사말에 알맞은 인사말로 답한다. 또는 손을 흔들거나 고개를 숙이는 등 인사말에 어울리는 표정이나 몸짓으로 반응한다.
A6: 초1~2 | B6: 듣기 | C6: 1 | D6: 2 | E6: 2 | F6: L-1-2-2 | G6: 초1~2-듣기-02 | H6: 간단한 인사말을 듣고 이해할 수 있다. | I6: 만나고 헤어질 때 인사말(안녕히 가세요, 내일 봐요. 등)에 알맞은 표정이나 몸짓으로 반응한다. | J6: 학생과 헤어지는 상황에서 다음 인사말 중 하나를 한다. ① “안녕히 가세요.“ ② “내일 봐요.“ ③ “잘 가요.“ | K6: 교사의 인사말에 알맞은 인사말로 답한다. 또는 손을 흔들거나 고개를 숙이는 등 인사말에 어울리는 표정이나 몸짓으로 반응한다.
A7: 초1~2 | B7: 듣기 | C7: 1 | D7: 3 | E7: 1 | F7: L-1-3-1 | G7: 초1~2-듣기-03 | H7: 교사의 간단한 지시를 듣고 따를 수 있다. | I7: 교사의 행동 지시(일어나세요, 앉으세요.등)를 듣고, 해당 행동을 수행한다. | J7: 다음 행동 지시 중 하나를 한다. ① “일어나세요.“ ② “앉으세요.“ ③ “손을 드세요.“ | K7: 교사의 지시를 듣고 해당 행동을 그대로 수행한다.
A8: 초1~2 | B8: 듣기 | C8: 1 | D8: 3 | E8: 2 | F8: L-1-3-2 | G8: 초1~2-듣기-03 | H8: 교사의 간단한 지시를 듣고 따를 수 있다. | I8: 교사의 방향을 포함한 지시(오른쪽으로 가세요. 교실로 들어가세요. 등)를 듣고, 해당 행동을 수행한다. | J8: 다음 방향 지시 중 하나를 한다. ① “오른쪽으로 가세요.“ ② “교실로 들어가세요.“ ③ “앞으로 나오세요.“ | K8: 교사의 지시를 듣고 알맞은 방향으로 이동한다.
A9: 초1~2 | B9: 듣기 | C9: 1 | D9: 3 | E9: 3 | F9: L-1-3-3 | G9: 초1~2-듣기-03 | H9: 교사의 간단한 지시를 듣고 따를 수 있다. | I9: 목적어/부사어를 포함한 지시(책을 펴세요, 이름을 쓰세요. 자리에 앉으세요. 등)를 듣고, 해당 행동을 수행한다. | J9: 다음 행동 지시 중 하나를 한다. ① “책을 펴세요.“ ② “이름을 쓰세요.“ ③ “자리에 앉으세요.“ | K9: 교사의 지시를 듣고 책을 펴거나, 이름을 쓰거나, 자리에 앉는 등 해당 행동을 수행한다.
A10: 초1~2 | B10: 듣기 | C10: 1 | D10: 4 | E10: 1 | F10: L-1-4-1 | G10: 초1~2-듣기-04 | H10: 자음과 모음을 듣고 식별할 수 있다. | I10: 교사가 모음(아, 야 등)을 말하면, 해당 모음을 고른다. | J10: 모음 카드 여러 장(아, 야, 어, 여 등)을 학생 앞에 늘어놓고 “아“, “야“처럼 모음 하나를 천천히 말한다. | K10: 교사가 말한 모음 카드를 손가락으로 가리키거나 집어 든다.
A11: 초1~2 | B11: 듣기 | C11: 1 | D11: 4 | E11: 2 | F11: L-1-4-2 | G11: 초1~2-듣기-04 | H11: 자음과 모음을 듣고 식별할 수 있다. | I11: 교사가 자음의 음가(드,르 등)를 말하면, 해당 자음을 고른다. | J11: 자음 카드 여러 장(ㄷ, ㄹ, ㅁ, ㅂ 등)을 학생 앞에 늘어놓고 “드“, “르“처럼 자음 음가 하나를 천천히 말한다. | K11: 교사가 말한 자음 카드를 손가락으로 가리키거나 집어 든다.
A12: 초1~2 | B12: 듣기 | C12: 2 | D12: 1 | E12: 1 | F12: L-2-1-1 | G12: 초1~2-듣기-05 | H12: 교실에서 자주 사용하는 기초적인 대화 내용을 이해할 수 있다. | I12: 도움을 요청하는 대화(가위 주세요./ 여기 있어요.등)를 듣고, 교사의 질문(지금 어떤 도움이 필요하니? 등)에 적절한 답을 한다. | J12: 도움을 요청하는 짧은 대화를 학생에게 들려준다. [듣기 대본 - 남자아이와 여자아이가 서로 한 마디씩 말을 주고받는 상황] 남자아이: 가위 주세요. (2초 간격) 여자아이: 여기 있어요. 이어서 "지금 어떤 도움이 필요해요?"라고 묻는다. | K12: "가위 주세요.", "지우개 주세요."처럼 도움이 필요한 내용을 한 문장으로 답한다.
A13: 초1~2 | B13: 듣기 | C13: 2 | D13: 1 | E13: 2 | F13: L-2-1-2 | G13: 초1~2-듣기-05 | H13: 교실에서 자주 사용하는 기초적인 대화 내용을 이해할 수 있다. | I13: 정보를 묻는 대화(몇 학년 몇 반이에요? /1학년 2반이에요. 등)를 듣고, 안내된 정보를 고른다. | J13: 정보를 묻는 짧은 대화를 학생에게 들려준다. [듣기 대본1 - 남자아이와 여자아이가 서로 한 마디씩 말을 주고받는 상황] 남자아이: 몇 학년 몇 반이에요? (2초 간격) 여자아이: 1학년 2반이에요. [듣기 대본2 - 남자아이와 여자아이가 서로 한 마디씩 말을 주고받는 상황] 남자아이: 어느 나라에서 왔어요? (2초 간격) 여자아이: 중국이요. 이어서 보기 그림이나 숫자 카드를 보여 주고 "몇 학년 몇 반이에요?", "어느 나라에서 왔어요?"라고 묻는다. | K13: 대화에서 들은 학년과 반 정보를 보기에서 골라 가리키거나 답한다.
... A515: 초5~6 | B515: 쓰기 | C515: 4 | D515: 4 | E515: 3 | F515: W-4-4-3 | G515: 초5~6-쓰기-16 | H515: 일상과 학교생활에서 필요한 여러 유형의 글을 쓸 수 있다. | I515: 온라인 공간(학교 홈페이지나 학급 밴드 등)에 올릴 게시글을 쓸 때, 매체의 특성(인터넷 예절, 사진 첨부 등)을 고려하여 적절한 형식과 언어로 쓴다. | J515: "학교 홈페이지나 학급 밴드에 게시글을 써 보세요."라고 한다. | K515: 인터넷 예절을 지키고 필요한 경우 사진 첨부를 안내하는 글을 쓴다. (학생 작성 예) 제목: 5월 학급 미술 작품 안내 안녕하세요, 저는 미술부장 OOO입니다. 이번 5월 미술 시간에 학생들이 만든 작품 사진을 올립니다. (사진 첨부) 모든 친구가 정성껏 만든 작품이니 따뜻한 응원 부탁드립니다. 댓글로 격려의 말씀 남겨 주시면 학생들에게 큰 힘이 됩니다. - 인터넷 예절: 친구의 작품에 대해 부정적인 댓글은 쓰지 말아 주세요.

Sheet 원고 확인 사항
A1: 번호 | B1: 구분 | C1: 파일 | D1: 위치(코드) | E1: 내용 | F1: 제안 | G1: 처리
A2: 1 | B2: 성취수준 번호 | C2: 초1~2 읽기 | D2: R-2-3-1~2, R-2-4-1~2 | E2: 머리말이 "성취수준 2"로 표기됨(코드상 성취수준 3·4) | F2: 머리말 번호를 코드에 맞게 수정
A3: 2 | B3: 성취수준 번호 | C3: 초1~2 읽기 | D3: R-3-1 ~ R-3-4 (R-3-3 제외) | E3: 머리말이 모두 "성취수준 3"으로 표기됨(수준 번호를 쓴 것으로 보임) | F3: 성취수준 1·2·4로 수정
A4: 3 | B4: 성취수준 번호 | C4: 초1~2 읽기 | D4: R-4-1 ~ R-4-3 | E4: 머리말이 모두 "성취수준 4"로 표기됨 | F4: 성취수준 1·2·3으로 수정
A5: 4 | B5: 성취수준 번호 | C5: 초1~2 말하기 | D5: S-3-2-1 | E5: 머리말 "성취수준 1"(코드상 2). S-3-2-2·3은 "성취수준 2" | F5: "성취수준 2"로 수정
A6: 5 | B6: 문항 번호 | C6: 초1~2 말하기 | D6: S-2-1-2, S-2-1-3 | E6: 표 머리의 문항 번호가 "1번"으로 표기됨(코드상 2번·3번) | F6: 문항 번호 수정
A7: 6 | B7: 머리말 누락 | C7: 초1~2 쓰기 | D7: W-1-4-1 | E7: 성취수준 4 머리말이 없고 앞 성취수준 3 문장이 그대로 들어감 | F7: "4. 단순한 시각 자료를 보고 해당하는 단어를 쓸 수 있다." 넣기
A8: 7 | B8: 성취수준 번호 | C8: 초5~6 말하기 | D8: S-2-3-2 | E8: 머리말 "성취수준 2"(코드상 3) | F8: "성취수준 3"으로 수정
A9: 8 | B9: 임시 문구 | C9: 초5~6 말하기 | D9: S-3-3-3 | E9: 머리말이 "성취수준 기술문"(임시 문구). 교사·학생 절차 없음 | F9: 성취수준 문장과 진단 절차 보완
A10: 9 | B10: 절차 누락(추출 기준) | C10: 초1~2 읽기 | D10: R-3-4-2, R-4-1-1, R-4-1-3 | E10: 교사·학생 절차 텍스트가 추출되지 않음(이미지이거나 누락) | F10: 원본 PDF에서 확인
A11: 10 | B11: 맞춤법 | C11: 초1~2 말하기 | D11: S-1-3-2 | E11: 몇 살이예요? | F11: 몇 살이에요?
A12: 11 | B12: 맞춤법 | C12: 초1~2 말하기 | D12: S-2-5-1 | E12: 이것은 내 가방이예요. | F12: 가방이에요.
A13: 12 | B13: 맞춤법 | C13: 초3~4 듣기 | D13: L-2-4-2 | E13: 무슨 요일이예요? | F13: 요일이에요?
... A17: 16 | B17: 참고 | C17: 초1~2·초3~4 | D17: 1수준 듣기·말하기·읽기·쓰기 | E17: 두 학년군의 1수준 문항이 대부분 같은 문장 | F17: 콘텐츠 공통 제작 검토
A19: ※ PDF 텍스트를 자동 추출해 대조한 결과입니다. 원본에서 한 번 더 확인해 주세요.

Sheet 제작 체크리스트
A1: 구분 | B1: 항목 | C1: 내용 | D1: 비고(듣기06 경험) | E1: 확인
A2: 원고 | B2: 차시 명세서 표준화 | C2: 차시마다 진단 코드, 학습 목표, 활동별 발문·대본·보기·정답·피드백 문구, 사용 이미지를 같은 양식으로 작성 | D2: claude_prompt.md가 사실상 명세서. 표 한 줄 = 1차시로 정리하면 대량 제작 가능
A3: 원고 | B3: 듣기 대본 검수 | C3: 숫자·단위가 들어간 문장은 화면 표기와 읽기 문장을 따로 지정 | D3: "교과서 10쪽"을 "열 쪽"으로 읽은 문제 → "십 쪽"으로 따로 지정해 해결
A4: 원고 | B4: 피드백 문구 톤 | C4: "틀려도 괜찮아요" 톤 유지. 안내문의 "시험이 아니다" 원칙과 맞춤
A5: 템플릿 | B5: 공통 화면 구조 | C5: 도입 → 목표 → 활동 안내 → 활동 1~4 → 마무리. 1600×900 기준 화면 비율 맞춤 | D5: 현재 듣기06 디자인을 템플릿으로 고정하고 내용 데이터만 교체
A6: 템플릿 | B6: 활동 유형 모음 | C6: 고르기·여러 개 고르기·순서 놓기·선 잇기·표시하기·따라 쓰기·카드 조합·녹음 비교 | D6: 진단 수행(가리키기·배열·연결)을 화면 활동으로 옮김
A7: 템플릿 | B7: 정답·오답 피드백 | C7: 화면 가운데 큰 팝업, 정답일 때만 다음으로 이동 | D7: 듣기06에서 적용함
A8: 음성 | B8: 음성 방식 결정 | C8: 브라우저 음성 합성은 기기·브라우저마다 목소리와 발음이 다름. 대화문은 2인 이상 화자 필요 | D8: 녹음 파일(성우 또는 음성 생성 후 파일 포함) 전환 검토
A9: 음성 | B9: 말하기 녹음 | C9: 브라우저 음성 인식은 크롬 전용이고 아동·비원어민 인식률이 낮음 → 녹음·다시 듣기·모범 발음 비교, 판정은 교사 | D9: 아동 음성은 저장하지 않음(개인정보)
A10: 쓰기 | B10: 쓰기 입력 방식 | C10: 따라 쓰기는 터치 필기 화면 + 획순 애니메이션, 문장 쓰기는 낱말 카드 조합, 서술형은 예시 답안 + 교사 확인 | D10: 저학년은 한글 자판 입력이 어려움
A11: 이미지 | B11: 공용 이미지 묶음 | C11: 주제별(학용품·장소·음식·감정 등)로 같은 톤·같은 크기로 정리 | D11: 듣기06에서 배경 제거·밝기·크기 맞춤 작업을 함
A12: 이미지 | B12: 저작권 확인 | C12: 진단도구 그림 카드, ICMS 사진, 캐릭터(온라인 캡처)의 이용 범위 확인 | D12: 교과서 표지·상표가 사진에 남아 있음
A13: 이미지 | B13: 학년군별 디자인 톤 | C13: 초5~6에 저학년용 캐릭터·톤을 그대로 쓰면 유치하게 느낄 수 있음
A14: 환경 | B14: 터치 대응 | C14: 학교 태블릿에서 끌어 놓기가 되도록 터치 이벤트 사용 | D14: HTML5 끌어 놓기는 터치에서 작동하지 않을 수 있음
A15: 환경 | B15: 파일 구조 | C15: 차시당 단일 파일(약 0.6MB) 유지 또는 공용 이미지 분리 결정
A16: 환경 | B16: 배포 규격 | C16: "모두의 한국어" 사이트 업로드 형식·용량·접근성 기준 확인 | D16: 미확인
A17: 학습자 | B17: 모국어 도움 | C17: 지시문 음성은 필수, 필요하면 모국어 안내 추가 | D17: 안내문 유의점과 같은 취지
A18: 연계 | B18: 진단 연계 표시 | C18: 차시 화면이나 교사용 안내에 진단 코드를 표시해 미도달 성취수준 → 해당 차시 → 재진단으로 이어지게 함
A19: 검수 | B19: 검수 절차 | C19: 문구·음성·정답 판정을 원고와 자동 대조 + 실제 기기에서 소리 확인 | D19: 듣기06은 매 수정마다 원본과 문구·음성·판정을 자동 대조함
